Performing system checks...

System check identified no issues (0 silenced).
November 05, 2018 - 15:49:25
Django version 1.10, using settings 'gentelella.settings'
Starting development server at http://0:8000/
Quit the server with CONTROL-C.
[05/Nov/2018 15:50:16] "GET /form.html HTTP/1.1" 200 41029
[05/Nov/2018 15:50:16] "GET /static/build/css/custom.css HTTP/1.1" 304 0
[05/Nov/2018 15:50:19] "GET /form_upload.html HTTP/1.1" 200 31173
Forbidden (CSRF cookie not set.): /form_upload
[05/Nov/2018 15:50:21] "POST /form_upload HTTP/1.1" 403 2857
[05/Nov/2018 15:50:55] "GET /form_upload HTTP/1.1" 200 11
[05/Nov/2018 15:51:00] "GET /form_upload HTTP/1.1" 200 11
[05/Nov/2018 15:51:07] "GET /form_upload HTTP/1.1" 200 11
[05/Nov/2018 15:54:33] "GET /form_upload.html HTTP/1.1" 200 31173
Forbidden (CSRF cookie not set.): /form_upload
[05/Nov/2018 15:54:36] "POST /form_upload HTTP/1.1" 403 2857
[05/Nov/2018 15:56:56] "GET /form_upload.html HTTP/1.1" 200 31172
Forbidden (CSRF cookie not set.): /form_upload
[05/Nov/2018 15:56:59] "POST /form_upload HTTP/1.1" 403 2857
[05/Nov/2018 16:01:09] "GET /form_upload.html HTTP/1.1" 200 31307
[05/Nov/2018 16:01:13] "POST /form_upload HTTP/1.1" 200 11
Performing system checks...

System check identified no issues (0 silenced).
November 05, 2018 - 15:49:58
Django version 1.10, using settings 'gentelella.settings'
Starting development server at http://0:8000/
Quit the server with CONTROL-C.
Performing system checks...

System check identified no issues (0 silenced).
November 05, 2018 - 16:01:59
Django version 1.10, using settings 'gentelella.settings'
Starting development server at http://0:8000/
Quit the server with CONTROL-C.
Performing system checks...

System check identified no issues (0 silenced).
November 05, 2018 - 16:03:34
Django version 1.10, using settings 'gentelella.settings'
Starting development server at http://0:8000/
Quit the server with CONTROL-C.
Unhandled exception in thread started by <function check_errors.<locals>.wrapper at 0x7f6a9364b400>
Traceback (most recent call last):
  File "/usr/local/python3.6/lib/python3.6/site-packages/django/utils/autoreload.py", line 226, in wrapper
    fn(*args, **kwargs)
  File "/usr/local/python3.6/lib/python3.6/site-packages/django/core/management/commands/runserver.py", line 121, in inner_run
    self.check(display_num_errors=True)
  File "/usr/local/python3.6/lib/python3.6/site-packages/django/core/management/base.py", line 385, in check
    include_deployment_checks=include_deployment_checks,
  File "/usr/local/python3.6/lib/python3.6/site-packages/django/core/management/base.py", line 372, in _run_checks
    return checks.run_checks(**kwargs)
  File "/usr/local/python3.6/lib/python3.6/site-packages/django/core/checks/registry.py", line 81, in run_checks
    new_errors = check(app_configs=app_configs)
  File "/usr/local/python3.6/lib/python3.6/site-packages/django/core/checks/urls.py", line 14, in check_url_config
    return check_resolver(resolver)
  File "/usr/local/python3.6/lib/python3.6/site-packages/django/core/checks/urls.py", line 24, in check_resolver
    for pattern in resolver.url_patterns:
  File "/usr/local/python3.6/lib/python3.6/site-packages/django/utils/functional.py", line 35, in __get__
    res = instance.__dict__[self.name] = self.func(instance)
  File "/usr/local/python3.6/lib/python3.6/site-packages/django/urls/resolvers.py", line 310, in url_patterns
    patterns = getattr(self.urlconf_module, "urlpatterns", self.urlconf_module)
  File "/usr/local/python3.6/lib/python3.6/site-packages/django/utils/functional.py", line 35, in __get__
    res = instance.__dict__[self.name] = self.func(instance)
  File "/usr/local/python3.6/lib/python3.6/site-packages/django/urls/resolvers.py", line 303, in urlconf_module
    return import_module(self.urlconf_name)
  File "/usr/local/python3.6/lib/python3.6/importlib/__init__.py", line 126, in import_module
    return _bootstrap._gcd_import(name[level:], package, level)
  File "<frozen importlib._bootstrap>", line 994, in _gcd_import
  File "<frozen importlib._bootstrap>", line 971, in _find_and_load
  File "<frozen importlib._bootstrap>", line 955, in _find_and_load_unlocked
  File "<frozen importlib._bootstrap>", line 665, in _load_unlocked
  File "<frozen importlib._bootstrap_external>", line 678, in exec_module
  File "<frozen importlib._bootstrap>", line 219, in _call_with_frames_removed
  File "/srv/django-gentelella/gentelella/gentelella/urls.py", line 23, in <module>
    url(r'^app/', include('app.urls')),
  File "/usr/local/python3.6/lib/python3.6/site-packages/django/conf/urls/__init__.py", line 50, in include
    urlconf_module = import_module(urlconf_module)
  File "/usr/local/python3.6/lib/python3.6/importlib/__init__.py", line 126, in import_module
    return _bootstrap._gcd_import(name[level:], package, level)
  File "<frozen importlib._bootstrap>", line 994, in _gcd_import
  File "<frozen importlib._bootstrap>", line 971, in _find_and_load
  File "<frozen importlib._bootstrap>", line 955, in _find_and_load_unlocked
  File "<frozen importlib._bootstrap>", line 665, in _load_unlocked
  File "<frozen importlib._bootstrap_external>", line 674, in exec_module
  File "<frozen importlib._bootstrap_external>", line 781, in get_code
  File "<frozen importlib._bootstrap_external>", line 741, in source_to_code
  File "<frozen importlib._bootstrap>", line 219, in _call_with_frames_removed
  File "/srv/django-gentelella/gentelella/app/urls.py", line 12
    url(r'^form_upload$',./scripts/form_upload.py)
                         ^
SyntaxError: invalid syntax
Performing system checks...

[05/Nov/2018 16:31:31] "GET /form_upload.html HTTP/1.1" 200 31307
[05/Nov/2018 16:31:34] "GET /form_upload.html HTTP/1.1" 200 31307
[05/Nov/2018 16:31:37] "POST /form_upload HTTP/1.1" 200 11
Performing system checks...

System check identified no issues (0 silenced).
November 05, 2018 - 16:31:01
Django version 1.10, using settings 'gentelella.settings'
Starting development server at http://0:8000/
Quit the server with CONTROL-C.
Unhandled exception in thread started by <function check_errors.<locals>.wrapper at 0x7f2f15837400>
Traceback (most recent call last):
  File "/usr/local/python3.6/lib/python3.6/site-packages/django/utils/autoreload.py", line 226, in wrapper
    fn(*args, **kwargs)
  File "/usr/local/python3.6/lib/python3.6/site-packages/django/core/management/commands/runserver.py", line 121, in inner_run
    self.check(display_num_errors=True)
  File "/usr/local/python3.6/lib/python3.6/site-packages/django/core/management/base.py", line 385, in check
    include_deployment_checks=include_deployment_checks,
  File "/usr/local/python3.6/lib/python3.6/site-packages/django/core/management/base.py", line 372, in _run_checks
    return checks.run_checks(**kwargs)
  File "/usr/local/python3.6/lib/python3.6/site-packages/django/core/checks/registry.py", line 81, in run_checks
    new_errors = check(app_configs=app_configs)
  File "/usr/local/python3.6/lib/python3.6/site-packages/django/core/checks/urls.py", line 14, in check_url_config
    return check_resolver(resolver)
  File "/usr/local/python3.6/lib/python3.6/site-packages/django/core/checks/urls.py", line 24, in check_resolver
    for pattern in resolver.url_patterns:
  File "/usr/local/python3.6/lib/python3.6/site-packages/django/utils/functional.py", line 35, in __get__
    res = instance.__dict__[self.name] = self.func(instance)
  File "/usr/local/python3.6/lib/python3.6/site-packages/django/urls/resolvers.py", line 310, in url_patterns
    patterns = getattr(self.urlconf_module, "urlpatterns", self.urlconf_module)
  File "/usr/local/python3.6/lib/python3.6/site-packages/django/utils/functional.py", line 35, in __get__
    res = instance.__dict__[self.name] = self.func(instance)
  File "/usr/local/python3.6/lib/python3.6/site-packages/django/urls/resolvers.py", line 303, in urlconf_module
    return import_module(self.urlconf_name)
  File "/usr/local/python3.6/lib/python3.6/importlib/__init__.py", line 126, in import_module
    return _bootstrap._gcd_import(name[level:], package, level)
  File "<frozen importlib._bootstrap>", line 994, in _gcd_import
  File "<frozen importlib._bootstrap>", line 971, in _find_and_load
  File "<frozen importlib._bootstrap>", line 955, in _find_and_load_unlocked
  File "<frozen importlib._bootstrap>", line 665, in _load_unlocked
  File "<frozen importlib._bootstrap_external>", line 678, in exec_module
  File "<frozen importlib._bootstrap>", line 219, in _call_with_frames_removed
  File "/srv/django-gentelella/gentelella/gentelella/urls.py", line 23, in <module>
    url(r'^app/', include('app.urls')),
  File "/usr/local/python3.6/lib/python3.6/site-packages/django/conf/urls/__init__.py", line 50, in include
    urlconf_module = import_module(urlconf_module)
  File "/usr/local/python3.6/lib/python3.6/importlib/__init__.py", line 126, in import_module
    return _bootstrap._gcd_import(name[level:], package, level)
  File "<frozen importlib._bootstrap>", line 994, in _gcd_import
  File "<frozen importlib._bootstrap>", line 971, in _find_and_load
  File "<frozen importlib._bootstrap>", line 955, in _find_and_load_unlocked
  File "<frozen importlib._bootstrap>", line 665, in _load_unlocked
  File "<frozen importlib._bootstrap_external>", line 678, in exec_module
  File "<frozen importlib._bootstrap>", line 219, in _call_with_frames_removed
  File "/srv/django-gentelella/gentelella/app/urls.py", line 13, in <module>
    url(r'^form_upload$',scripts.form_upload.upload)
NameError: name 'scripts' is not defined
Performing system checks...

Unhandled exception in thread started by <function check_errors.<locals>.wrapper at 0x7f986f808400>
Traceback (most recent call last):
  File "/usr/local/python3.6/lib/python3.6/site-packages/django/utils/autoreload.py", line 226, in wrapper
    fn(*args, **kwargs)
  File "/usr/local/python3.6/lib/python3.6/site-packages/django/core/management/commands/runserver.py", line 121, in inner_run
    self.check(display_num_errors=True)
  File "/usr/local/python3.6/lib/python3.6/site-packages/django/core/management/base.py", line 385, in check
    include_deployment_checks=include_deployment_checks,
  File "/usr/local/python3.6/lib/python3.6/site-packages/django/core/management/base.py", line 372, in _run_checks
    return checks.run_checks(**kwargs)
  File "/usr/local/python3.6/lib/python3.6/site-packages/django/core/checks/registry.py", line 81, in run_checks
    new_errors = check(app_configs=app_configs)
  File "/usr/local/python3.6/lib/python3.6/site-packages/django/core/checks/urls.py", line 14, in check_url_config
    return check_resolver(resolver)
  File "/usr/local/python3.6/lib/python3.6/site-packages/django/core/checks/urls.py", line 24, in check_resolver
    for pattern in resolver.url_patterns:
  File "/usr/local/python3.6/lib/python3.6/site-packages/django/utils/functional.py", line 35, in __get__
    res = instance.__dict__[self.name] = self.func(instance)
  File "/usr/local/python3.6/lib/python3.6/site-packages/django/urls/resolvers.py", line 310, in url_patterns
    patterns = getattr(self.urlconf_module, "urlpatterns", self.urlconf_module)
  File "/usr/local/python3.6/lib/python3.6/site-packages/django/utils/functional.py", line 35, in __get__
    res = instance.__dict__[self.name] = self.func(instance)
  File "/usr/local/python3.6/lib/python3.6/site-packages/django/urls/resolvers.py", line 303, in urlconf_module
    return import_module(self.urlconf_name)
  File "/usr/local/python3.6/lib/python3.6/importlib/__init__.py", line 126, in import_module
    return _bootstrap._gcd_import(name[level:], package, level)
  File "<frozen importlib._bootstrap>", line 994, in _gcd_import
  File "<frozen importlib._bootstrap>", line 971, in _find_and_load
  File "<frozen importlib._bootstrap>", line 955, in _find_and_load_unlocked
  File "<frozen importlib._bootstrap>", line 665, in _load_unlocked
  File "<frozen importlib._bootstrap_external>", line 678, in exec_module
  File "<frozen importlib._bootstrap>", line 219, in _call_with_frames_removed
  File "/srv/django-gentelella/gentelella/gentelella/urls.py", line 23, in <module>
    url(r'^app/', include('app.urls')),
  File "/usr/local/python3.6/lib/python3.6/site-packages/django/conf/urls/__init__.py", line 50, in include
    urlconf_module = import_module(urlconf_module)
  File "/usr/local/python3.6/lib/python3.6/importlib/__init__.py", line 126, in import_module
    return _bootstrap._gcd_import(name[level:], package, level)
  File "<frozen importlib._bootstrap>", line 994, in _gcd_import
  File "<frozen importlib._bootstrap>", line 971, in _find_and_load
  File "<frozen importlib._bootstrap>", line 955, in _find_and_load_unlocked
  File "<frozen importlib._bootstrap>", line 665, in _load_unlocked
  File "<frozen importlib._bootstrap_external>", line 678, in exec_module
  File "<frozen importlib._bootstrap>", line 219, in _call_with_frames_removed
  File "/srv/django-gentelella/gentelella/app/urls.py", line 13, in <module>
    url(r'^form_upload$',scripts.form_upload)
NameError: name 'scripts' is not defined
Performing system checks...

Performing system checks...

System check identified no issues (0 silenced).
November 05, 2018 - 16:38:44
Django version 1.10, using settings 'gentelella.settings'
Starting development server at http://0:8000/
Quit the server with CONTROL-C.
[05/Nov/2018 16:39:38] "GET /form_upload.html HTTP/1.1" 200 31307
Performing system checks...

System check identified no issues (0 silenced).
November 05, 2018 - 16:39:04
Django version 1.10, using settings 'gentelella.settings'
Starting development server at http://0:8000/
Quit the server with CONTROL-C.
Unhandled exception in thread started by <function check_errors.<locals>.wrapper at 0x7fb52ae51400>
Traceback (most recent call last):
  File "/usr/local/python3.6/lib/python3.6/site-packages/django/utils/autoreload.py", line 226, in wrapper
    fn(*args, **kwargs)
  File "/usr/local/python3.6/lib/python3.6/site-packages/django/core/management/commands/runserver.py", line 121, in inner_run
    self.check(display_num_errors=True)
  File "/usr/local/python3.6/lib/python3.6/site-packages/django/core/management/base.py", line 385, in check
    include_deployment_checks=include_deployment_checks,
  File "/usr/local/python3.6/lib/python3.6/site-packages/django/core/management/base.py", line 372, in _run_checks
    return checks.run_checks(**kwargs)
  File "/usr/local/python3.6/lib/python3.6/site-packages/django/core/checks/registry.py", line 81, in run_checks
    new_errors = check(app_configs=app_configs)
  File "/usr/local/python3.6/lib/python3.6/site-packages/django/core/checks/urls.py", line 14, in check_url_config
    return check_resolver(resolver)
  File "/usr/local/python3.6/lib/python3.6/site-packages/django/core/checks/urls.py", line 24, in check_resolver
    for pattern in resolver.url_patterns:
  File "/usr/local/python3.6/lib/python3.6/site-packages/django/utils/functional.py", line 35, in __get__
    res = instance.__dict__[self.name] = self.func(instance)
  File "/usr/local/python3.6/lib/python3.6/site-packages/django/urls/resolvers.py", line 310, in url_patterns
    patterns = getattr(self.urlconf_module, "urlpatterns", self.urlconf_module)
  File "/usr/local/python3.6/lib/python3.6/site-packages/django/utils/functional.py", line 35, in __get__
    res = instance.__dict__[self.name] = self.func(instance)
  File "/usr/local/python3.6/lib/python3.6/site-packages/django/urls/resolvers.py", line 303, in urlconf_module
    return import_module(self.urlconf_name)
  File "/usr/local/python3.6/lib/python3.6/importlib/__init__.py", line 126, in import_module
    return _bootstrap._gcd_import(name[level:], package, level)
  File "<frozen importlib._bootstrap>", line 994, in _gcd_import
  File "<frozen importlib._bootstrap>", line 971, in _find_and_load
  File "<frozen importlib._bootstrap>", line 955, in _find_and_load_unlocked
  File "<frozen importlib._bootstrap>", line 665, in _load_unlocked
  File "<frozen importlib._bootstrap_external>", line 678, in exec_module
  File "<frozen importlib._bootstrap>", line 219, in _call_with_frames_removed
  File "/srv/django-gentelella/gentelella/gentelella/urls.py", line 23, in <module>
    url(r'^app/', include('app.urls')),
  File "/usr/local/python3.6/lib/python3.6/site-packages/django/conf/urls/__init__.py", line 50, in include
    urlconf_module = import_module(urlconf_module)
  File "/usr/local/python3.6/lib/python3.6/importlib/__init__.py", line 126, in import_module
    return _bootstrap._gcd_import(name[level:], package, level)
  File "<frozen importlib._bootstrap>", line 994, in _gcd_import
  File "<frozen importlib._bootstrap>", line 971, in _find_and_load
  File "<frozen importlib._bootstrap>", line 955, in _find_and_load_unlocked
  File "<frozen importlib._bootstrap>", line 665, in _load_unlocked
  File "<frozen importlib._bootstrap_external>", line 678, in exec_module
  File "<frozen importlib._bootstrap>", line 219, in _call_with_frames_removed
  File "/srv/django-gentelella/gentelella/app/urls.py", line 2, in <module>
    from app import views
  File "/srv/django-gentelella/gentelella/app/views.py", line 28
    **initial={'subject': 'I love you site!'}**
             ^
SyntaxError: invalid syntax
Performing system checks...

[06/Nov/2018 09:48:19] "GET / HTTP/1.1" 200 43415
[06/Nov/2018 09:48:20] "GET /static/vendors/bootstrap/dist/css/bootstrap.min.css HTTP/1.1" 304 0
[06/Nov/2018 09:48:20] "GET /static/vendors/font-awesome/css/font-awesome.min.css HTTP/1.1" 304 0
[06/Nov/2018 09:48:20] "GET /static/vendors/nprogress/nprogress.css HTTP/1.1" 304 0
[06/Nov/2018 09:48:20] "GET /static/vendors/iCheck/skins/flat/green.css HTTP/1.1" 304 0
[06/Nov/2018 09:48:20] "GET /static/vendors/bootstrap-daterangepicker/daterangepicker.css HTTP/1.1" 304 0
[06/Nov/2018 09:48:20] "GET /static/vendors/bootstrap-progressbar/css/bootstrap-progressbar-3.3.4.min.css HTTP/1.1" 304 0
[06/Nov/2018 09:48:20] "GET /static/vendors/jqvmap/dist/jqvmap.min.css HTTP/1.1" 304 0
[06/Nov/2018 09:48:20] "GET /static/build/css/custom.css HTTP/1.1" 304 0
[06/Nov/2018 09:48:20] "GET /static/vendors/jquery/dist/jquery.min.js HTTP/1.1" 304 0
[06/Nov/2018 09:48:20] "GET /static/vendors/bootstrap/dist/js/bootstrap.min.js HTTP/1.1" 304 0
[06/Nov/2018 09:48:20] "GET /static/vendors/fastclick/lib/fastclick.js HTTP/1.1" 304 0
[06/Nov/2018 09:48:20] "GET /static/vendors/nprogress/nprogress.js HTTP/1.1" 304 0
[06/Nov/2018 09:48:20] "GET /static/vendors/bootstrap-progressbar/bootstrap-progressbar.min.js HTTP/1.1" 304 0
[06/Nov/2018 09:48:20] "GET /static/vendors/iCheck/icheck.min.js HTTP/1.1" 304 0
[06/Nov/2018 09:48:20] "GET /static/vendors/moment/min/moment.min.js HTTP/1.1" 304 0
[06/Nov/2018 09:48:20] "GET /static/vendors/bootstrap-daterangepicker/daterangepicker.js HTTP/1.1" 304 0
[06/Nov/2018 09:48:20] "GET /static/vendors/bootstrap-wysiwyg/js/bootstrap-wysiwyg.min.js HTTP/1.1" 304 0
[06/Nov/2018 09:48:20] "GET /static/vendors/jquery.hotkeys/jquery.hotkeys.js HTTP/1.1" 304 0
[06/Nov/2018 09:48:20] "GET /static/vendors/google-code-prettify/src/prettify.js HTTP/1.1" 304 0
[06/Nov/2018 09:48:20] "GET /static/vendors/jquery.tagsinput/src/jquery.tagsinput.js HTTP/1.1" 304 0
[06/Nov/2018 09:48:20] "GET /static/vendors/switchery/dist/switchery.min.js HTTP/1.1" 304 0
[06/Nov/2018 09:48:20] "GET /static/vendors/bootstrap/dist/fonts/glyphicons-halflings-regular.woff2 HTTP/1.1" 304 0
[06/Nov/2018 09:48:20] "GET /static/vendors/font-awesome/fonts/fontawesome-webfont.woff2?v=4.6.3 HTTP/1.1" 304 0
[06/Nov/2018 09:48:20] "GET /static/vendors/parsleyjs/dist/parsley.min.js HTTP/1.1" 304 0
[06/Nov/2018 09:48:20] "GET /static/vendors/select2/dist/js/select2.full.min.js HTTP/1.1" 304 0
[06/Nov/2018 09:48:20] "GET /static/vendors/autosize/dist/autosize.min.js HTTP/1.1" 304 0
[06/Nov/2018 09:48:20] "GET /static/vendors/devbridge-autocomplete/dist/jquery.autocomplete.min.js HTTP/1.1" 304 0
[06/Nov/2018 09:48:20] "GET /static/vendors/starrr/dist/starrr.js HTTP/1.1" 304 0
[06/Nov/2018 09:48:20] "GET /static/vendors/Chart.js/dist/Chart.min.js HTTP/1.1" 304 0
[06/Nov/2018 09:48:20] "GET /static/vendors/gauge.js/dist/gauge.min.js HTTP/1.1" 304 0
[06/Nov/2018 09:48:20] "GET /static/vendors/skycons/skycons.js HTTP/1.1" 304 0
[06/Nov/2018 09:48:20] "GET /static/vendors/Flot/jquery.flot.js HTTP/1.1" 304 0
[06/Nov/2018 09:48:20] "GET /static/vendors/Flot/jquery.flot.pie.js HTTP/1.1" 304 0
[06/Nov/2018 09:48:20] "GET /static/vendors/Flot/jquery.flot.time.js HTTP/1.1" 304 0
[06/Nov/2018 09:48:20] "GET /static/vendors/Flot/jquery.flot.resize.js HTTP/1.1" 304 0
[06/Nov/2018 09:48:20] "GET /static/vendors/Flot/jquery.flot.stack.js HTTP/1.1" 304 0
[06/Nov/2018 09:48:20] "GET /static/vendors/flot.orderbars/js/jquery.flot.orderBars.js HTTP/1.1" 304 0
[06/Nov/2018 09:48:20] "GET /static/vendors/flot-spline/js/jquery.flot.spline.min.js HTTP/1.1" 304 0
[06/Nov/2018 09:48:20] "GET /static/vendors/flot.curvedlines/curvedLines.js HTTP/1.1" 304 0
[06/Nov/2018 09:48:20] "GET /static/vendors/DateJS/build/date.js HTTP/1.1" 304 0
[06/Nov/2018 09:48:20] "GET /static/vendors/jqvmap/dist/jquery.vmap.js HTTP/1.1" 304 0
[06/Nov/2018 09:48:20] "GET /static/vendors/jqvmap/examples/js/jquery.vmap.sampledata.js HTTP/1.1" 304 0
[06/Nov/2018 09:48:20] "GET /static/vendors/jqvmap/dist/maps/jquery.vmap.world.js HTTP/1.1" 304 0
[06/Nov/2018 09:48:20] "GET /static/build/js/custom.js HTTP/1.1" 304 0
[06/Nov/2018 09:48:20] "GET /static/images/img.jpg HTTP/1.1" 304 0
[06/Nov/2018 09:48:20] "GET /static/vendors/iCheck/skins/flat/green.png HTTP/1.1" 304 0
Not Found: /favicon.ico
[06/Nov/2018 09:48:20] "GET /favicon.ico HTTP/1.1" 404 2552
[06/Nov/2018 09:48:22] "GET /form.html HTTP/1.1" 200 41029
[06/Nov/2018 09:48:22] "GET /static/vendors/datatables.net/js/jquery.dataTables.min.js HTTP/1.1" 304 0
[06/Nov/2018 09:48:22] "GET /static/vendors/datatables.net-bs/js/dataTables.bootstrap.min.js HTTP/1.1" 304 0
[06/Nov/2018 09:48:22] "GET /static/vendors/datatables.net-buttons/js/dataTables.buttons.min.js HTTP/1.1" 304 0
[06/Nov/2018 09:48:22] "GET /static/vendors/datatables.net-buttons-bs/js/buttons.bootstrap.min.js HTTP/1.1" 304 0
[06/Nov/2018 09:48:22] "GET /static/vendors/datatables.net-buttons/js/buttons.flash.min.js HTTP/1.1" 304 0
[06/Nov/2018 09:48:22] "GET /static/vendors/datatables.net-buttons/js/buttons.html5.min.js HTTP/1.1" 304 0
[06/Nov/2018 09:48:22] "GET /static/vendors/datatables.net-buttons/js/buttons.print.min.js HTTP/1.1" 304 0
[06/Nov/2018 09:48:22] "GET /static/vendors/datatables.net-fixedheader/js/dataTables.fixedHeader.min.js HTTP/1.1" 304 0
[06/Nov/2018 09:48:22] "GET /static/vendors/datatables.net-keytable/js/dataTables.keyTable.min.js HTTP/1.1" 304 0
[06/Nov/2018 09:48:22] "GET /static/vendors/datatables.net-responsive/js/dataTables.responsive.min.js HTTP/1.1" 304 0
[06/Nov/2018 09:48:22] "GET /static/vendors/datatables.net-responsive-bs/js/responsive.bootstrap.js HTTP/1.1" 304 0
[06/Nov/2018 09:48:22] "GET /static/vendors/datatables.net-scroller/js/dataTables.scroller.min.js HTTP/1.1" 304 0
[06/Nov/2018 09:48:22] "GET /static/vendors/jszip/dist/jszip.min.js HTTP/1.1" 304 0
[06/Nov/2018 09:48:22] "GET /static/vendors/pdfmake/build/pdfmake.min.js HTTP/1.1" 304 0
[06/Nov/2018 09:48:22] "GET /static/vendors/pdfmake/build/vfs_fonts.js HTTP/1.1" 304 0
[06/Nov/2018 09:48:24] "GET /form_upload.html HTTP/1.1" 200 31308
[06/Nov/2018 09:48:24] "GET /static/vendors/dropzone/dist/min/dropzone.min.css HTTP/1.1" 304 0
[06/Nov/2018 09:48:24] "GET /static/vendors/dropzone/dist/min/dropzone.min.js HTTP/1.1" 304 0
[06/Nov/2018 09:48:24] "GET /static/vendors/jQuery-Smart-Wizard/js/jquery.smartWizard.js HTTP/1.1" 304 0
[06/Nov/2018 09:48:27] "POST /form_upload HTTP/1.1" 200 2
[06/Nov/2018 09:48:34] "GET /static/vendors/parsleyjs/dist/parsley.min.js.map HTTP/1.1" 304 0
[06/Nov/2018 09:48:34] "GET /static/vendors/bootstrap/dist/css/bootstrap.min.css.map HTTP/1.1" 304 0
[06/Nov/2018 09:48:55] "GET /form_upload.html HTTP/1.1" 200 31308
[06/Nov/2018 09:49:02] "POST /form_upload HTTP/1.1" 200 2
Performing system checks...

System check identified no issues (0 silenced).
November 06, 2018 - 09:48:13
Django version 1.10, using settings 'gentelella.settings'
Starting development server at http://0:8000/
Quit the server with CONTROL-C.
tuotu.png
tuotu.png
[06/Nov/2018 09:49:52] "GET /form_upload.html HTTP/1.1" 200 31308
[06/Nov/2018 09:49:58] "POST /form_upload HTTP/1.1" 200 163265
Performing system checks...

System check identified no issues (0 silenced).
November 06, 2018 - 09:49:51
Django version 1.10, using settings 'gentelella.settings'
Starting development server at http://0:8000/
Quit the server with CONTROL-C.
tuotu.png
Unhandled exception in thread started by <function check_errors.<locals>.wrapper at 0x7f2d7c4de400>
Traceback (most recent call last):
  File "/usr/local/python3.6/lib/python3.6/site-packages/django/utils/autoreload.py", line 226, in wrapper
    fn(*args, **kwargs)
  File "/usr/local/python3.6/lib/python3.6/site-packages/django/core/management/commands/runserver.py", line 121, in inner_run
    self.check(display_num_errors=True)
  File "/usr/local/python3.6/lib/python3.6/site-packages/django/core/management/base.py", line 385, in check
    include_deployment_checks=include_deployment_checks,
  File "/usr/local/python3.6/lib/python3.6/site-packages/django/core/management/base.py", line 372, in _run_checks
    return checks.run_checks(**kwargs)
  File "/usr/local/python3.6/lib/python3.6/site-packages/django/core/checks/registry.py", line 81, in run_checks
    new_errors = check(app_configs=app_configs)
  File "/usr/local/python3.6/lib/python3.6/site-packages/django/core/checks/urls.py", line 14, in check_url_config
    return check_resolver(resolver)
  File "/usr/local/python3.6/lib/python3.6/site-packages/django/core/checks/urls.py", line 24, in check_resolver
    for pattern in resolver.url_patterns:
  File "/usr/local/python3.6/lib/python3.6/site-packages/django/utils/functional.py", line 35, in __get__
    res = instance.__dict__[self.name] = self.func(instance)
  File "/usr/local/python3.6/lib/python3.6/site-packages/django/urls/resolvers.py", line 310, in url_patterns
    patterns = getattr(self.urlconf_module, "urlpatterns", self.urlconf_module)
  File "/usr/local/python3.6/lib/python3.6/site-packages/django/utils/functional.py", line 35, in __get__
    res = instance.__dict__[self.name] = self.func(instance)
  File "/usr/local/python3.6/lib/python3.6/site-packages/django/urls/resolvers.py", line 303, in urlconf_module
    return import_module(self.urlconf_name)
  File "/usr/local/python3.6/lib/python3.6/importlib/__init__.py", line 126, in import_module
    return _bootstrap._gcd_import(name[level:], package, level)
  File "<frozen importlib._bootstrap>", line 994, in _gcd_import
  File "<frozen importlib._bootstrap>", line 971, in _find_and_load
  File "<frozen importlib._bootstrap>", line 955, in _find_and_load_unlocked
  File "<frozen importlib._bootstrap>", line 665, in _load_unlocked
  File "<frozen importlib._bootstrap_external>", line 678, in exec_module
  File "<frozen importlib._bootstrap>", line 219, in _call_with_frames_removed
  File "/srv/django-gentelella/gentelella/gentelella/urls.py", line 23, in <module>
    url(r'^app/', include('app.urls')),
  File "/usr/local/python3.6/lib/python3.6/site-packages/django/conf/urls/__init__.py", line 50, in include
    urlconf_module = import_module(urlconf_module)
  File "/usr/local/python3.6/lib/python3.6/importlib/__init__.py", line 126, in import_module
    return _bootstrap._gcd_import(name[level:], package, level)
  File "<frozen importlib._bootstrap>", line 994, in _gcd_import
  File "<frozen importlib._bootstrap>", line 971, in _find_and_load
  File "<frozen importlib._bootstrap>", line 955, in _find_and_load_unlocked
  File "<frozen importlib._bootstrap>", line 665, in _load_unlocked
  File "<frozen importlib._bootstrap_external>", line 678, in exec_module
  File "<frozen importlib._bootstrap>", line 219, in _call_with_frames_removed
  File "/srv/django-gentelella/gentelella/app/urls.py", line 2, in <module>
    from app import views
  File "/srv/django-gentelella/gentelella/app/views.py", line 27
    return HttpResponse('name':name, 'file_type':file_type)
                              ^
SyntaxError: invalid syntax
Performing system checks...

[06/Nov/2018 09:54:59] "GET / HTTP/1.1" 200 43415
[06/Nov/2018 09:55:02] "GET /form_upload.html HTTP/1.1" 200 31308
----------------------------------------
Exception happened during processing of request from ('172.20.4.15', 51942)
Traceback (most recent call last):
  File "/usr/local/python3.6/lib/python3.6/socketserver.py", line 651, in process_request_thread
    self.finish_request(request, client_address)
  File "/usr/local/python3.6/lib/python3.6/socketserver.py", line 361, in finish_request
    self.RequestHandlerClass(request, client_address, self)
  File "/usr/local/python3.6/lib/python3.6/socketserver.py", line 721, in __init__
    self.handle()
  File "/usr/local/python3.6/lib/python3.6/site-packages/django/core/servers/basehttp.py", line 159, in handle
    self.raw_requestline = self.rfile.readline(65537)
  File "/usr/local/python3.6/lib/python3.6/socket.py", line 586, in readinto
    return self._sock.recv_into(b)
ConnectionResetError: [Errno 104] Connection reset by peer
----------------------------------------
Performing system checks...

System check identified no issues (0 silenced).
November 06, 2018 - 09:54:58
Django version 1.10, using settings 'gentelella.settings'
Starting development server at http://0:8000/
Quit the server with CONTROL-C.
Unhandled exception in thread started by <function check_errors.<locals>.wrapper at 0x7f4657d5a400>
Traceback (most recent call last):
  File "/usr/local/python3.6/lib/python3.6/site-packages/django/utils/autoreload.py", line 226, in wrapper
    fn(*args, **kwargs)
  File "/usr/local/python3.6/lib/python3.6/site-packages/django/core/management/commands/runserver.py", line 121, in inner_run
    self.check(display_num_errors=True)
  File "/usr/local/python3.6/lib/python3.6/site-packages/django/core/management/base.py", line 385, in check
    include_deployment_checks=include_deployment_checks,
  File "/usr/local/python3.6/lib/python3.6/site-packages/django/core/management/base.py", line 372, in _run_checks
    return checks.run_checks(**kwargs)
  File "/usr/local/python3.6/lib/python3.6/site-packages/django/core/checks/registry.py", line 81, in run_checks
    new_errors = check(app_configs=app_configs)
  File "/usr/local/python3.6/lib/python3.6/site-packages/django/core/checks/urls.py", line 14, in check_url_config
    return check_resolver(resolver)
  File "/usr/local/python3.6/lib/python3.6/site-packages/django/core/checks/urls.py", line 24, in check_resolver
    for pattern in resolver.url_patterns:
  File "/usr/local/python3.6/lib/python3.6/site-packages/django/utils/functional.py", line 35, in __get__
    res = instance.__dict__[self.name] = self.func(instance)
  File "/usr/local/python3.6/lib/python3.6/site-packages/django/urls/resolvers.py", line 310, in url_patterns
    patterns = getattr(self.urlconf_module, "urlpatterns", self.urlconf_module)
  File "/usr/local/python3.6/lib/python3.6/site-packages/django/utils/functional.py", line 35, in __get__
    res = instance.__dict__[self.name] = self.func(instance)
  File "/usr/local/python3.6/lib/python3.6/site-packages/django/urls/resolvers.py", line 303, in urlconf_module
    return import_module(self.urlconf_name)
  File "/usr/local/python3.6/lib/python3.6/importlib/__init__.py", line 126, in import_module
    return _bootstrap._gcd_import(name[level:], package, level)
  File "<frozen importlib._bootstrap>", line 994, in _gcd_import
  File "<frozen importlib._bootstrap>", line 971, in _find_and_load
  File "<frozen importlib._bootstrap>", line 955, in _find_and_load_unlocked
  File "<frozen importlib._bootstrap>", line 665, in _load_unlocked
  File "<frozen importlib._bootstrap_external>", line 678, in exec_module
  File "<frozen importlib._bootstrap>", line 219, in _call_with_frames_removed
  File "/srv/django-gentelella/gentelella/gentelella/urls.py", line 23, in <module>
    url(r'^app/', include('app.urls')),
  File "/usr/local/python3.6/lib/python3.6/site-packages/django/conf/urls/__init__.py", line 50, in include
    urlconf_module = import_module(urlconf_module)
  File "/usr/local/python3.6/lib/python3.6/importlib/__init__.py", line 126, in import_module
    return _bootstrap._gcd_import(name[level:], package, level)
  File "<frozen importlib._bootstrap>", line 994, in _gcd_import
  File "<frozen importlib._bootstrap>", line 971, in _find_and_load
  File "<frozen importlib._bootstrap>", line 955, in _find_and_load_unlocked
  File "<frozen importlib._bootstrap>", line 665, in _load_unlocked
  File "<frozen importlib._bootstrap_external>", line 678, in exec_module
  File "<frozen importlib._bootstrap>", line 219, in _call_with_frames_removed
  File "/srv/django-gentelella/gentelella/app/urls.py", line 2, in <module>
    from app import views
  File "/srv/django-gentelella/gentelella/app/views.py", line 28
    f = open(/tmp/file_obj.name,'wb')
             ^
SyntaxError: invalid syntax
Performing system checks...

Unhandled exception in thread started by <function check_errors.<locals>.wrapper at 0x7f71303d7400>
Traceback (most recent call last):
  File "/usr/local/python3.6/lib/python3.6/site-packages/django/utils/autoreload.py", line 226, in wrapper
    fn(*args, **kwargs)
  File "/usr/local/python3.6/lib/python3.6/site-packages/django/core/management/commands/runserver.py", line 121, in inner_run
    self.check(display_num_errors=True)
  File "/usr/local/python3.6/lib/python3.6/site-packages/django/core/management/base.py", line 385, in check
    include_deployment_checks=include_deployment_checks,
  File "/usr/local/python3.6/lib/python3.6/site-packages/django/core/management/base.py", line 372, in _run_checks
    return checks.run_checks(**kwargs)
  File "/usr/local/python3.6/lib/python3.6/site-packages/django/core/checks/registry.py", line 81, in run_checks
    new_errors = check(app_configs=app_configs)
  File "/usr/local/python3.6/lib/python3.6/site-packages/django/core/checks/urls.py", line 14, in check_url_config
    return check_resolver(resolver)
  File "/usr/local/python3.6/lib/python3.6/site-packages/django/core/checks/urls.py", line 24, in check_resolver
    for pattern in resolver.url_patterns:
  File "/usr/local/python3.6/lib/python3.6/site-packages/django/utils/functional.py", line 35, in __get__
    res = instance.__dict__[self.name] = self.func(instance)
  File "/usr/local/python3.6/lib/python3.6/site-packages/django/urls/resolvers.py", line 310, in url_patterns
    patterns = getattr(self.urlconf_module, "urlpatterns", self.urlconf_module)
  File "/usr/local/python3.6/lib/python3.6/site-packages/django/utils/functional.py", line 35, in __get__
    res = instance.__dict__[self.name] = self.func(instance)
  File "/usr/local/python3.6/lib/python3.6/site-packages/django/urls/resolvers.py", line 303, in urlconf_module
    return import_module(self.urlconf_name)
  File "/usr/local/python3.6/lib/python3.6/importlib/__init__.py", line 126, in import_module
    return _bootstrap._gcd_import(name[level:], package, level)
  File "<frozen importlib._bootstrap>", line 994, in _gcd_import
  File "<frozen importlib._bootstrap>", line 971, in _find_and_load
  File "<frozen importlib._bootstrap>", line 955, in _find_and_load_unlocked
  File "<frozen importlib._bootstrap>", line 665, in _load_unlocked
  File "<frozen importlib._bootstrap_external>", line 678, in exec_module
  File "<frozen importlib._bootstrap>", line 219, in _call_with_frames_removed
  File "/srv/django-gentelella/gentelella/gentelella/urls.py", line 23, in <module>
    url(r'^app/', include('app.urls')),
  File "/usr/local/python3.6/lib/python3.6/site-packages/django/conf/urls/__init__.py", line 50, in include
    urlconf_module = import_module(urlconf_module)
  File "/usr/local/python3.6/lib/python3.6/importlib/__init__.py", line 126, in import_module
    return _bootstrap._gcd_import(name[level:], package, level)
  File "<frozen importlib._bootstrap>", line 994, in _gcd_import
  File "<frozen importlib._bootstrap>", line 971, in _find_and_load
  File "<frozen importlib._bootstrap>", line 955, in _find_and_load_unlocked
  File "<frozen importlib._bootstrap>", line 665, in _load_unlocked
  File "<frozen importlib._bootstrap_external>", line 678, in exec_module
  File "<frozen importlib._bootstrap>", line 219, in _call_with_frames_removed
  File "/srv/django-gentelella/gentelella/app/urls.py", line 2, in <module>
    from app import views
  File "/srv/django-gentelella/gentelella/app/views.py", line 28
    f = open(/tmp/file_obj.name,'wb')
             ^
SyntaxError: invalid syntax
Performing system checks...

Unhandled exception in thread started by <function check_errors.<locals>.wrapper at 0x7f0defdc3400>
Traceback (most recent call last):
  File "/usr/local/python3.6/lib/python3.6/site-packages/django/utils/autoreload.py", line 226, in wrapper
    fn(*args, **kwargs)
  File "/usr/local/python3.6/lib/python3.6/site-packages/django/core/management/commands/runserver.py", line 121, in inner_run
    self.check(display_num_errors=True)
  File "/usr/local/python3.6/lib/python3.6/site-packages/django/core/management/base.py", line 385, in check
    include_deployment_checks=include_deployment_checks,
  File "/usr/local/python3.6/lib/python3.6/site-packages/django/core/management/base.py", line 372, in _run_checks
    return checks.run_checks(**kwargs)
  File "/usr/local/python3.6/lib/python3.6/site-packages/django/core/checks/registry.py", line 81, in run_checks
    new_errors = check(app_configs=app_configs)
  File "/usr/local/python3.6/lib/python3.6/site-packages/django/core/checks/urls.py", line 14, in check_url_config
    return check_resolver(resolver)
  File "/usr/local/python3.6/lib/python3.6/site-packages/django/core/checks/urls.py", line 24, in check_resolver
    for pattern in resolver.url_patterns:
  File "/usr/local/python3.6/lib/python3.6/site-packages/django/utils/functional.py", line 35, in __get__
    res = instance.__dict__[self.name] = self.func(instance)
  File "/usr/local/python3.6/lib/python3.6/site-packages/django/urls/resolvers.py", line 310, in url_patterns
    patterns = getattr(self.urlconf_module, "urlpatterns", self.urlconf_module)
  File "/usr/local/python3.6/lib/python3.6/site-packages/django/utils/functional.py", line 35, in __get__
    res = instance.__dict__[self.name] = self.func(instance)
  File "/usr/local/python3.6/lib/python3.6/site-packages/django/urls/resolvers.py", line 303, in urlconf_module
    return import_module(self.urlconf_name)
  File "/usr/local/python3.6/lib/python3.6/importlib/__init__.py", line 126, in import_module
    return _bootstrap._gcd_import(name[level:], package, level)
  File "<frozen importlib._bootstrap>", line 994, in _gcd_import
  File "<frozen importlib._bootstrap>", line 971, in _find_and_load
  File "<frozen importlib._bootstrap>", line 955, in _find_and_load_unlocked
  File "<frozen importlib._bootstrap>", line 665, in _load_unlocked
  File "<frozen importlib._bootstrap_external>", line 678, in exec_module
  File "<frozen importlib._bootstrap>", line 219, in _call_with_frames_removed
  File "/srv/django-gentelella/gentelella/gentelella/urls.py", line 23, in <module>
    url(r'^app/', include('app.urls')),
  File "/usr/local/python3.6/lib/python3.6/site-packages/django/conf/urls/__init__.py", line 50, in include
    urlconf_module = import_module(urlconf_module)
  File "/usr/local/python3.6/lib/python3.6/importlib/__init__.py", line 126, in import_module
    return _bootstrap._gcd_import(name[level:], package, level)
  File "<frozen importlib._bootstrap>", line 994, in _gcd_import
  File "<frozen importlib._bootstrap>", line 971, in _find_and_load
  File "<frozen importlib._bootstrap>", line 955, in _find_and_load_unlocked
  File "<frozen importlib._bootstrap>", line 665, in _load_unlocked
  File "<frozen importlib._bootstrap_external>", line 678, in exec_module
  File "<frozen importlib._bootstrap>", line 219, in _call_with_frames_removed
  File "/srv/django-gentelella/gentelella/app/urls.py", line 2, in <module>
    from app import views
  File "/srv/django-gentelella/gentelella/app/views.py", line 29
    f.write(name,file_type)
    ^
IndentationError: unexpected indent
Performing system checks...

[06/Nov/2018 10:12:15] "GET /form_upload.html HTTP/1.1" 200 31308
[06/Nov/2018 10:12:19] "GET /form_upload.html HTTP/1.1" 200 31308
Internal Server Error: /form_upload
Traceback (most recent call last):
  File "/usr/local/python3.6/lib/python3.6/site-packages/django/core/handlers/exception.py", line 39, in inner
    response = get_response(request)
  File "/usr/local/python3.6/lib/python3.6/site-packages/django/core/handlers/base.py", line 187, in _get_response
    response = self.process_exception_by_middleware(e, request)
  File "/usr/local/python3.6/lib/python3.6/site-packages/django/core/handlers/base.py", line 185, in _get_response
    response = wrapped_callback(request, *callback_args, **callback_kwargs)
  File "/srv/django-gentelella/gentelella/app/views.py", line 29, in form_upload
    f.write(name,file_type)
TypeError: write() takes exactly one argument (2 given)
[06/Nov/2018 10:12:21] "POST /form_upload HTTP/1.1" 500 13915
[06/Nov/2018 10:12:36] "GET /form.html HTTP/1.1" 200 41029
[06/Nov/2018 10:12:36] "GET /static/vendors/pdfmake/build/pdfmake.min.js.map HTTP/1.1" 304 0
[06/Nov/2018 10:12:37] "GET /form_upload.html HTTP/1.1" 200 31308
Internal Server Error: /form_upload
Traceback (most recent call last):
  File "/usr/local/python3.6/lib/python3.6/site-packages/django/core/handlers/exception.py", line 39, in inner
    response = get_response(request)
  File "/usr/local/python3.6/lib/python3.6/site-packages/django/core/handlers/base.py", line 187, in _get_response
    response = self.process_exception_by_middleware(e, request)
  File "/usr/local/python3.6/lib/python3.6/site-packages/django/core/handlers/base.py", line 185, in _get_response
    response = wrapped_callback(request, *callback_args, **callback_kwargs)
  File "/srv/django-gentelella/gentelella/app/views.py", line 29, in form_upload
    f.write(name,file_type)
TypeError: write() takes exactly one argument (2 given)
[06/Nov/2018 10:12:40] "POST /form_upload HTTP/1.1" 500 13915
[06/Nov/2018 10:13:20] "GET /form.html HTTP/1.1" 200 41029
[06/Nov/2018 10:13:21] "GET /form_upload.html HTTP/1.1" 200 31308
Internal Server Error: /form_upload
Traceback (most recent call last):
  File "/usr/local/python3.6/lib/python3.6/site-packages/django/core/handlers/exception.py", line 39, in inner
    response = get_response(request)
  File "/usr/local/python3.6/lib/python3.6/site-packages/django/core/handlers/base.py", line 187, in _get_response
    response = self.process_exception_by_middleware(e, request)
  File "/usr/local/python3.6/lib/python3.6/site-packages/django/core/handlers/base.py", line 185, in _get_response
    response = wrapped_callback(request, *callback_args, **callback_kwargs)
  File "/srv/django-gentelella/gentelella/app/views.py", line 29, in form_upload
    f.write(name,file_type)
TypeError: write() takes exactly one argument (2 given)
[06/Nov/2018 10:13:24] "POST /form_upload HTTP/1.1" 500 13915
Performing system checks...

System check identified no issues (0 silenced).
November 06, 2018 - 10:12:00
Django version 1.10, using settings 'gentelella.settings'
Starting development server at http://0:8000/
Quit the server with CONTROL-C.
[06/Nov/2018 10:15:08] "GET /form_upload.html HTTP/1.1" 200 31308
[06/Nov/2018 10:15:10] "GET /form.html HTTP/1.1" 200 41029
[06/Nov/2018 10:15:11] "GET /form_upload.html HTTP/1.1" 200 31308
Internal Server Error: /form_upload
Traceback (most recent call last):
  File "/usr/local/python3.6/lib/python3.6/site-packages/django/core/handlers/exception.py", line 39, in inner
    response = get_response(request)
  File "/usr/local/python3.6/lib/python3.6/site-packages/django/core/handlers/base.py", line 187, in _get_response
    response = self.process_exception_by_middleware(e, request)
  File "/usr/local/python3.6/lib/python3.6/site-packages/django/core/handlers/base.py", line 185, in _get_response
    response = wrapped_callback(request, *callback_args, **callback_kwargs)
  File "/srv/django-gentelella/gentelella/app/views.py", line 29, in form_upload
    f.write(name)
TypeError: a bytes-like object is required, not 'str'
[06/Nov/2018 10:15:14] "POST /form_upload HTTP/1.1" 500 13901
Performing system checks...

System check identified no issues (0 silenced).
November 06, 2018 - 10:15:03
Django version 1.10, using settings 'gentelella.settings'
Starting development server at http://0:8000/
Quit the server with CONTROL-C.
[06/Nov/2018 10:17:03] "GET /form.html HTTP/1.1" 200 41029
[06/Nov/2018 10:17:05] "GET /form_upload.html HTTP/1.1" 200 31308
[06/Nov/2018 10:17:08] "POST /form_upload HTTP/1.1" 200 2
Performing system checks...

System check identified no issues (0 silenced).
November 06, 2018 - 10:16:55
Django version 1.10, using settings 'gentelella.settings'
Starting development server at http://0:8000/
Quit the server with CONTROL-C.
tuotu.png <class 'django.core.files.uploadedfile.InMemoryUploadedFile'>
111111
Unhandled exception in thread started by <function check_errors.<locals>.wrapper at 0x7f4d4d6c8400>
Traceback (most recent call last):
  File "/usr/local/python3.6/lib/python3.6/site-packages/django/utils/autoreload.py", line 226, in wrapper
    fn(*args, **kwargs)
  File "/usr/local/python3.6/lib/python3.6/site-packages/django/core/management/commands/runserver.py", line 121, in inner_run
    self.check(display_num_errors=True)
  File "/usr/local/python3.6/lib/python3.6/site-packages/django/core/management/base.py", line 385, in check
    include_deployment_checks=include_deployment_checks,
  File "/usr/local/python3.6/lib/python3.6/site-packages/django/core/management/base.py", line 372, in _run_checks
    return checks.run_checks(**kwargs)
  File "/usr/local/python3.6/lib/python3.6/site-packages/django/core/checks/registry.py", line 81, in run_checks
    new_errors = check(app_configs=app_configs)
  File "/usr/local/python3.6/lib/python3.6/site-packages/django/core/checks/urls.py", line 14, in check_url_config
    return check_resolver(resolver)
  File "/usr/local/python3.6/lib/python3.6/site-packages/django/core/checks/urls.py", line 24, in check_resolver
    for pattern in resolver.url_patterns:
  File "/usr/local/python3.6/lib/python3.6/site-packages/django/utils/functional.py", line 35, in __get__
    res = instance.__dict__[self.name] = self.func(instance)
  File "/usr/local/python3.6/lib/python3.6/site-packages/django/urls/resolvers.py", line 310, in url_patterns
    patterns = getattr(self.urlconf_module, "urlpatterns", self.urlconf_module)
  File "/usr/local/python3.6/lib/python3.6/site-packages/django/utils/functional.py", line 35, in __get__
    res = instance.__dict__[self.name] = self.func(instance)
  File "/usr/local/python3.6/lib/python3.6/site-packages/django/urls/resolvers.py", line 303, in urlconf_module
    return import_module(self.urlconf_name)
  File "/usr/local/python3.6/lib/python3.6/importlib/__init__.py", line 126, in import_module
    return _bootstrap._gcd_import(name[level:], package, level)
  File "<frozen importlib._bootstrap>", line 994, in _gcd_import
  File "<frozen importlib._bootstrap>", line 971, in _find_and_load
  File "<frozen importlib._bootstrap>", line 955, in _find_and_load_unlocked
  File "<frozen importlib._bootstrap>", line 665, in _load_unlocked
  File "<frozen importlib._bootstrap_external>", line 678, in exec_module
  File "<frozen importlib._bootstrap>", line 219, in _call_with_frames_removed
  File "/srv/django-gentelella/gentelella/gentelella/urls.py", line 23, in <module>
    url(r'^app/', include('app.urls')),
  File "/usr/local/python3.6/lib/python3.6/site-packages/django/conf/urls/__init__.py", line 50, in include
    urlconf_module = import_module(urlconf_module)
  File "/usr/local/python3.6/lib/python3.6/importlib/__init__.py", line 126, in import_module
    return _bootstrap._gcd_import(name[level:], package, level)
  File "<frozen importlib._bootstrap>", line 994, in _gcd_import
  File "<frozen importlib._bootstrap>", line 971, in _find_and_load
  File "<frozen importlib._bootstrap>", line 955, in _find_and_load_unlocked
  File "<frozen importlib._bootstrap>", line 665, in _load_unlocked
  File "<frozen importlib._bootstrap_external>", line 678, in exec_module
  File "<frozen importlib._bootstrap>", line 219, in _call_with_frames_removed
  File "/srv/django-gentelella/gentelella/app/urls.py", line 2, in <module>
    from app import views
  File "/srv/django-gentelella/gentelella/app/views.py", line 29
    f.write(file_type)
    ^
IndentationError: unexpected indent
Performing system checks...

Unhandled exception in thread started by <function check_errors.<locals>.wrapper at 0x7f9dfe2c6400>
Traceback (most recent call last):
  File "/usr/local/python3.6/lib/python3.6/site-packages/django/utils/autoreload.py", line 226, in wrapper
    fn(*args, **kwargs)
  File "/usr/local/python3.6/lib/python3.6/site-packages/django/core/management/commands/runserver.py", line 121, in inner_run
    self.check(display_num_errors=True)
  File "/usr/local/python3.6/lib/python3.6/site-packages/django/core/management/base.py", line 385, in check
    include_deployment_checks=include_deployment_checks,
  File "/usr/local/python3.6/lib/python3.6/site-packages/django/core/management/base.py", line 372, in _run_checks
    return checks.run_checks(**kwargs)
  File "/usr/local/python3.6/lib/python3.6/site-packages/django/core/checks/registry.py", line 81, in run_checks
    new_errors = check(app_configs=app_configs)
  File "/usr/local/python3.6/lib/python3.6/site-packages/django/core/checks/urls.py", line 14, in check_url_config
    return check_resolver(resolver)
  File "/usr/local/python3.6/lib/python3.6/site-packages/django/core/checks/urls.py", line 24, in check_resolver
    for pattern in resolver.url_patterns:
  File "/usr/local/python3.6/lib/python3.6/site-packages/django/utils/functional.py", line 35, in __get__
    res = instance.__dict__[self.name] = self.func(instance)
  File "/usr/local/python3.6/lib/python3.6/site-packages/django/urls/resolvers.py", line 310, in url_patterns
    patterns = getattr(self.urlconf_module, "urlpatterns", self.urlconf_module)
  File "/usr/local/python3.6/lib/python3.6/site-packages/django/utils/functional.py", line 35, in __get__
    res = instance.__dict__[self.name] = self.func(instance)
  File "/usr/local/python3.6/lib/python3.6/site-packages/django/urls/resolvers.py", line 303, in urlconf_module
    return import_module(self.urlconf_name)
  File "/usr/local/python3.6/lib/python3.6/importlib/__init__.py", line 126, in import_module
    return _bootstrap._gcd_import(name[level:], package, level)
  File "<frozen importlib._bootstrap>", line 994, in _gcd_import
  File "<frozen importlib._bootstrap>", line 971, in _find_and_load
  File "<frozen importlib._bootstrap>", line 955, in _find_and_load_unlocked
  File "<frozen importlib._bootstrap>", line 665, in _load_unlocked
  File "<frozen importlib._bootstrap_external>", line 678, in exec_module
  File "<frozen importlib._bootstrap>", line 219, in _call_with_frames_removed
  File "/srv/django-gentelella/gentelella/gentelella/urls.py", line 23, in <module>
    url(r'^app/', include('app.urls')),
  File "/usr/local/python3.6/lib/python3.6/site-packages/django/conf/urls/__init__.py", line 50, in include
    urlconf_module = import_module(urlconf_module)
  File "/usr/local/python3.6/lib/python3.6/importlib/__init__.py", line 126, in import_module
    return _bootstrap._gcd_import(name[level:], package, level)
  File "<frozen importlib._bootstrap>", line 994, in _gcd_import
  File "<frozen importlib._bootstrap>", line 971, in _find_and_load
  File "<frozen importlib._bootstrap>", line 955, in _find_and_load_unlocked
  File "<frozen importlib._bootstrap>", line 665, in _load_unlocked
  File "<frozen importlib._bootstrap_external>", line 678, in exec_module
  File "<frozen importlib._bootstrap>", line 219, in _call_with_frames_removed
  File "/srv/django-gentelella/gentelella/app/urls.py", line 2, in <module>
    from app import views
  File "/srv/django-gentelella/gentelella/app/views.py", line 30
    f.write("-------------------")
    ^
IndentationError: unexpected indent
Performing system checks...

Unhandled exception in thread started by <function check_errors.<locals>.wrapper at 0x7fbd89e31400>
Traceback (most recent call last):
  File "/usr/local/python3.6/lib/python3.6/site-packages/django/utils/autoreload.py", line 226, in wrapper
    fn(*args, **kwargs)
  File "/usr/local/python3.6/lib/python3.6/site-packages/django/core/management/commands/runserver.py", line 121, in inner_run
    self.check(display_num_errors=True)
  File "/usr/local/python3.6/lib/python3.6/site-packages/django/core/management/base.py", line 385, in check
    include_deployment_checks=include_deployment_checks,
  File "/usr/local/python3.6/lib/python3.6/site-packages/django/core/management/base.py", line 372, in _run_checks
    return checks.run_checks(**kwargs)
  File "/usr/local/python3.6/lib/python3.6/site-packages/django/core/checks/registry.py", line 81, in run_checks
    new_errors = check(app_configs=app_configs)
  File "/usr/local/python3.6/lib/python3.6/site-packages/django/core/checks/urls.py", line 14, in check_url_config
    return check_resolver(resolver)
  File "/usr/local/python3.6/lib/python3.6/site-packages/django/core/checks/urls.py", line 24, in check_resolver
    for pattern in resolver.url_patterns:
  File "/usr/local/python3.6/lib/python3.6/site-packages/django/utils/functional.py", line 35, in __get__
    res = instance.__dict__[self.name] = self.func(instance)
  File "/usr/local/python3.6/lib/python3.6/site-packages/django/urls/resolvers.py", line 310, in url_patterns
    patterns = getattr(self.urlconf_module, "urlpatterns", self.urlconf_module)
  File "/usr/local/python3.6/lib/python3.6/site-packages/django/utils/functional.py", line 35, in __get__
    res = instance.__dict__[self.name] = self.func(instance)
  File "/usr/local/python3.6/lib/python3.6/site-packages/django/urls/resolvers.py", line 303, in urlconf_module
    return import_module(self.urlconf_name)
  File "/usr/local/python3.6/lib/python3.6/importlib/__init__.py", line 126, in import_module
    return _bootstrap._gcd_import(name[level:], package, level)
  File "<frozen importlib._bootstrap>", line 994, in _gcd_import
  File "<frozen importlib._bootstrap>", line 971, in _find_and_load
  File "<frozen importlib._bootstrap>", line 955, in _find_and_load_unlocked
  File "<frozen importlib._bootstrap>", line 665, in _load_unlocked
  File "<frozen importlib._bootstrap_external>", line 678, in exec_module
  File "<frozen importlib._bootstrap>", line 219, in _call_with_frames_removed
  File "/srv/django-gentelella/gentelella/gentelella/urls.py", line 23, in <module>
    url(r'^app/', include('app.urls')),
  File "/usr/local/python3.6/lib/python3.6/site-packages/django/conf/urls/__init__.py", line 50, in include
    urlconf_module = import_module(urlconf_module)
  File "/usr/local/python3.6/lib/python3.6/importlib/__init__.py", line 126, in import_module
    return _bootstrap._gcd_import(name[level:], package, level)
  File "<frozen importlib._bootstrap>", line 994, in _gcd_import
  File "<frozen importlib._bootstrap>", line 971, in _find_and_load
  File "<frozen importlib._bootstrap>", line 955, in _find_and_load_unlocked
  File "<frozen importlib._bootstrap>", line 665, in _load_unlocked
  File "<frozen importlib._bootstrap_external>", line 678, in exec_module
  File "<frozen importlib._bootstrap>", line 219, in _call_with_frames_removed
  File "/srv/django-gentelella/gentelella/app/urls.py", line 2, in <module>
    from app import views
  File "/srv/django-gentelella/gentelella/app/views.py", line 30
    f.write("-------------------")
    ^
IndentationError: unexpected indent
Performing system checks...

Performing system checks...

System check identified no issues (0 silenced).
November 06, 2018 - 10:26:09
Django version 1.10, using settings 'gentelella.settings'
Starting development server at http://0:8000/
Quit the server with CONTROL-C.
[06/Nov/2018 10:26:23] "GET / HTTP/1.1" 200 43415
[06/Nov/2018 10:26:25] "GET /form.html HTTP/1.1" 200 41029
[06/Nov/2018 10:26:27] "GET /form_upload.html HTTP/1.1" 200 31308
Internal Server Error: /form_upload
Traceback (most recent call last):
  File "/usr/local/python3.6/lib/python3.6/site-packages/django/core/handlers/exception.py", line 39, in inner
    response = get_response(request)
  File "/usr/local/python3.6/lib/python3.6/site-packages/django/core/handlers/base.py", line 187, in _get_response
    response = self.process_exception_by_middleware(e, request)
  File "/usr/local/python3.6/lib/python3.6/site-packages/django/core/handlers/base.py", line 185, in _get_response
    response = wrapped_callback(request, *callback_args, **callback_kwargs)
  File "/srv/django-gentelella/gentelella/app/views.py", line 30, in form_upload
    f.write("-------------------")
TypeError: a bytes-like object is required, not 'str'
[06/Nov/2018 10:26:31] "POST /form_upload HTTP/1.1" 500 13918
Performing system checks...

System check identified no issues (0 silenced).
November 06, 2018 - 10:26:14
Django version 1.10, using settings 'gentelella.settings'
Starting development server at http://0:8000/
Quit the server with CONTROL-C.
[06/Nov/2018 10:28:27] "GET /form_upload.html HTTP/1.1" 200 31308
Internal Server Error: /form_upload
Traceback (most recent call last):
  File "/usr/local/python3.6/lib/python3.6/site-packages/django/core/handlers/exception.py", line 39, in inner
    response = get_response(request)
  File "/usr/local/python3.6/lib/python3.6/site-packages/django/core/handlers/base.py", line 187, in _get_response
    response = self.process_exception_by_middleware(e, request)
  File "/usr/local/python3.6/lib/python3.6/site-packages/django/core/handlers/base.py", line 185, in _get_response
    response = wrapped_callback(request, *callback_args, **callback_kwargs)
  File "/srv/django-gentelella/gentelella/app/views.py", line 30, in form_upload
    f.write('-------------------')
TypeError: a bytes-like object is required, not 'str'
[06/Nov/2018 10:28:35] "POST /form_upload HTTP/1.1" 500 13918
Performing system checks...

System check identified no issues (0 silenced).
November 06, 2018 - 10:28:14
Django version 1.10, using settings 'gentelella.settings'
Starting development server at http://0:8000/
Quit the server with CONTROL-C.
[06/Nov/2018 10:32:34] "GET /form_upload.html HTTP/1.1" 200 31308
[06/Nov/2018 10:32:36] "GET /form_upload.html HTTP/1.1" 200 31308
[06/Nov/2018 10:32:39] "POST /form_upload HTTP/1.1" 200 2
Performing system checks...

System check identified no issues (0 silenced).
November 06, 2018 - 10:32:28
Django version 1.10, using settings 'gentelella.settings'
Starting development server at http://0:8000/
Quit the server with CONTROL-C.
111111
[06/Nov/2018 10:33:18] "GET /form_upload.html HTTP/1.1" 200 31308
[06/Nov/2018 10:33:20] "GET /form.html HTTP/1.1" 200 41029
[06/Nov/2018 10:33:21] "GET /form_upload.html HTTP/1.1" 200 31308
Internal Server Error: /form_upload
Traceback (most recent call last):
  File "/usr/local/python3.6/lib/python3.6/site-packages/django/core/handlers/exception.py", line 39, in inner
    response = get_response(request)
  File "/usr/local/python3.6/lib/python3.6/site-packages/django/core/handlers/base.py", line 187, in _get_response
    response = self.process_exception_by_middleware(e, request)
  File "/usr/local/python3.6/lib/python3.6/site-packages/django/core/handlers/base.py", line 185, in _get_response
    response = wrapped_callback(request, *callback_args, **callback_kwargs)
  File "/srv/django-gentelella/gentelella/app/views.py", line 29, in form_upload
    f.write(file_type)
TypeError: write() argument must be str, not type
[06/Nov/2018 10:33:23] "POST /form_upload HTTP/1.1" 500 13898
Performing system checks...

System check identified no issues (0 silenced).
November 06, 2018 - 10:33:08
Django version 1.10, using settings 'gentelella.settings'
Starting development server at http://0:8000/
Quit the server with CONTROL-C.
[06/Nov/2018 10:34:32] "GET /form.html HTTP/1.1" 200 41029
[06/Nov/2018 10:34:33] "GET /form_upload.html HTTP/1.1" 200 31308
[06/Nov/2018 10:34:35] "POST /form_upload HTTP/1.1" 200 2
Performing system checks...

System check identified no issues (0 silenced).
November 06, 2018 - 10:34:22
Django version 1.10, using settings 'gentelella.settings'
Starting development server at http://0:8000/
Quit the server with CONTROL-C.
111111
[06/Nov/2018 10:35:24] "GET /form_upload.html HTTP/1.1" 200 31308
[06/Nov/2018 10:35:25] "GET /form_upload.html HTTP/1.1" 200 31308
[06/Nov/2018 10:35:28] "POST /form_upload HTTP/1.1" 200 2
Performing system checks...

System check identified no issues (0 silenced).
November 06, 2018 - 10:35:18
Django version 1.10, using settings 'gentelella.settings'
Starting development server at http://0:8000/
Quit the server with CONTROL-C.
111111
[06/Nov/2018 10:40:44] "GET /form_upload.html HTTP/1.1" 200 31308
[06/Nov/2018 10:40:45] "GET /form_upload.html HTTP/1.1" 200 31308
Internal Server Error: /form_upload
Traceback (most recent call last):
  File "/usr/local/python3.6/lib/python3.6/site-packages/django/core/handlers/exception.py", line 39, in inner
    response = get_response(request)
  File "/usr/local/python3.6/lib/python3.6/site-packages/django/core/handlers/base.py", line 187, in _get_response
    response = self.process_exception_by_middleware(e, request)
  File "/usr/local/python3.6/lib/python3.6/site-packages/django/core/handlers/base.py", line 185, in _get_response
    response = wrapped_callback(request, *callback_args, **callback_kwargs)
  File "/srv/django-gentelella/gentelella/app/views.py", line 32, in form_upload
    f.write(name,size)
TypeError: write() takes exactly one argument (2 given)
[06/Nov/2018 10:40:49] "POST /form_upload HTTP/1.1" 500 13910
Performing system checks...

System check identified no issues (0 silenced).
November 06, 2018 - 10:40:37
Django version 1.10, using settings 'gentelella.settings'
Starting development server at http://0:8000/
Quit the server with CONTROL-C.
Unhandled exception in thread started by <function check_errors.<locals>.wrapper at 0x7fd012119400>
Traceback (most recent call last):
  File "/usr/local/python3.6/lib/python3.6/site-packages/django/utils/autoreload.py", line 226, in wrapper
    fn(*args, **kwargs)
  File "/usr/local/python3.6/lib/python3.6/site-packages/django/core/management/commands/runserver.py", line 121, in inner_run
    self.check(display_num_errors=True)
  File "/usr/local/python3.6/lib/python3.6/site-packages/django/core/management/base.py", line 385, in check
    include_deployment_checks=include_deployment_checks,
  File "/usr/local/python3.6/lib/python3.6/site-packages/django/core/management/base.py", line 372, in _run_checks
    return checks.run_checks(**kwargs)
  File "/usr/local/python3.6/lib/python3.6/site-packages/django/core/checks/registry.py", line 81, in run_checks
    new_errors = check(app_configs=app_configs)
  File "/usr/local/python3.6/lib/python3.6/site-packages/django/core/checks/urls.py", line 14, in check_url_config
    return check_resolver(resolver)
  File "/usr/local/python3.6/lib/python3.6/site-packages/django/core/checks/urls.py", line 24, in check_resolver
    for pattern in resolver.url_patterns:
  File "/usr/local/python3.6/lib/python3.6/site-packages/django/utils/functional.py", line 35, in __get__
    res = instance.__dict__[self.name] = self.func(instance)
  File "/usr/local/python3.6/lib/python3.6/site-packages/django/urls/resolvers.py", line 310, in url_patterns
    patterns = getattr(self.urlconf_module, "urlpatterns", self.urlconf_module)
  File "/usr/local/python3.6/lib/python3.6/site-packages/django/utils/functional.py", line 35, in __get__
    res = instance.__dict__[self.name] = self.func(instance)
  File "/usr/local/python3.6/lib/python3.6/site-packages/django/urls/resolvers.py", line 303, in urlconf_module
    return import_module(self.urlconf_name)
  File "/usr/local/python3.6/lib/python3.6/importlib/__init__.py", line 126, in import_module
    return _bootstrap._gcd_import(name[level:], package, level)
  File "<frozen importlib._bootstrap>", line 994, in _gcd_import
  File "<frozen importlib._bootstrap>", line 971, in _find_and_load
  File "<frozen importlib._bootstrap>", line 955, in _find_and_load_unlocked
  File "<frozen importlib._bootstrap>", line 665, in _load_unlocked
  File "<frozen importlib._bootstrap_external>", line 678, in exec_module
  File "<frozen importlib._bootstrap>", line 219, in _call_with_frames_removed
  File "/srv/django-gentelella/gentelella/gentelella/urls.py", line 23, in <module>
    url(r'^app/', include('app.urls')),
  File "/usr/local/python3.6/lib/python3.6/site-packages/django/conf/urls/__init__.py", line 50, in include
    urlconf_module = import_module(urlconf_module)
  File "/usr/local/python3.6/lib/python3.6/importlib/__init__.py", line 126, in import_module
    return _bootstrap._gcd_import(name[level:], package, level)
  File "<frozen importlib._bootstrap>", line 994, in _gcd_import
  File "<frozen importlib._bootstrap>", line 971, in _find_and_load
  File "<frozen importlib._bootstrap>", line 955, in _find_and_load_unlocked
  File "<frozen importlib._bootstrap>", line 665, in _load_unlocked
  File "<frozen importlib._bootstrap_external>", line 678, in exec_module
  File "<frozen importlib._bootstrap>", line 219, in _call_with_frames_removed
  File "/srv/django-gentelella/gentelella/app/urls.py", line 2, in <module>
    from app import views
  File "/srv/django-gentelella/gentelella/app/views.py", line 32
    f.write('this content is %s,%s',% name size)
                                    ^
SyntaxError: invalid syntax
Performing system checks...

Performing system checks...

System check identified no issues (0 silenced).
November 06, 2018 - 10:44:20
Django version 1.10, using settings 'gentelella.settings'
Starting development server at http://0:8000/
Quit the server with CONTROL-C.
[06/Nov/2018 10:44:44] "GET /form_upload.html HTTP/1.1" 200 31308
Internal Server Error: /form_upload
Traceback (most recent call last):
  File "/usr/local/python3.6/lib/python3.6/site-packages/django/core/handlers/exception.py", line 39, in inner
    response = get_response(request)
  File "/usr/local/python3.6/lib/python3.6/site-packages/django/core/handlers/base.py", line 187, in _get_response
    response = self.process_exception_by_middleware(e, request)
  File "/usr/local/python3.6/lib/python3.6/site-packages/django/core/handlers/base.py", line 185, in _get_response
    response = wrapped_callback(request, *callback_args, **callback_kwargs)
  File "/srv/django-gentelella/gentelella/app/views.py", line 31, in form_upload
    content = name + ' \n' +size
TypeError: must be str, not int
[06/Nov/2018 10:44:47] "POST /form_upload HTTP/1.1" 500 13872
Performing system checks...

System check identified no issues (0 silenced).
November 06, 2018 - 10:44:36
Django version 1.10, using settings 'gentelella.settings'
Starting development server at http://0:8000/
Quit the server with CONTROL-C.
[06/Nov/2018 10:45:22] "GET /form_upload.html HTTP/1.1" 200 31308
[06/Nov/2018 10:45:24] "POST /form_upload HTTP/1.1" 200 2
Performing system checks...

System check identified no issues (0 silenced).
November 06, 2018 - 10:45:16
Django version 1.10, using settings 'gentelella.settings'
Starting development server at http://0:8000/
Quit the server with CONTROL-C.
111111
[06/Nov/2018 10:55:50] "GET /form_upload.html HTTP/1.1" 200 31308
Internal Server Error: /form_upload
Traceback (most recent call last):
  File "/usr/local/python3.6/lib/python3.6/site-packages/django/core/handlers/exception.py", line 39, in inner
    response = get_response(request)
  File "/usr/local/python3.6/lib/python3.6/site-packages/django/core/handlers/base.py", line 187, in _get_response
    response = self.process_exception_by_middleware(e, request)
  File "/usr/local/python3.6/lib/python3.6/site-packages/django/core/handlers/base.py", line 185, in _get_response
    response = wrapped_callback(request, *callback_args, **callback_kwargs)
  File "/srv/django-gentelella/gentelella/app/views.py", line 32, in form_upload
    for chunk in f.chunks():
AttributeError: '_io.TextIOWrapper' object has no attribute 'chunks'
[06/Nov/2018 10:55:53] "POST /form_upload HTTP/1.1" 500 13942
Performing system checks...

System check identified no issues (0 silenced).
November 06, 2018 - 10:55:15
Django version 1.10, using settings 'gentelella.settings'
Starting development server at http://0:8000/
Quit the server with CONTROL-C.
[06/Nov/2018 10:56:38] "GET /form_upload.html HTTP/1.1" 200 31308
[06/Nov/2018 10:56:40] "GET /form.html HTTP/1.1" 200 41029
[06/Nov/2018 10:56:41] "GET /form_upload.html HTTP/1.1" 200 31308
Internal Server Error: /form_upload
Traceback (most recent call last):
  File "/usr/local/python3.6/lib/python3.6/site-packages/django/core/handlers/exception.py", line 39, in inner
    response = get_response(request)
  File "/usr/local/python3.6/lib/python3.6/site-packages/django/core/handlers/base.py", line 187, in _get_response
    response = self.process_exception_by_middleware(e, request)
  File "/usr/local/python3.6/lib/python3.6/site-packages/django/core/handlers/base.py", line 185, in _get_response
    response = wrapped_callback(request, *callback_args, **callback_kwargs)
  File "/srv/django-gentelella/gentelella/app/views.py", line 33, in form_upload
    f.write(chunk)
TypeError: write() argument must be str, not bytes
[06/Nov/2018 10:56:45] "POST /form_upload HTTP/1.1" 500 13900
Performing system checks...

System check identified no issues (0 silenced).
November 06, 2018 - 10:56:29
Django version 1.10, using settings 'gentelella.settings'
Starting development server at http://0:8000/
Quit the server with CONTROL-C.
[06/Nov/2018 11:04:06] "GET /form_upload.html HTTP/1.1" 200 31308
[06/Nov/2018 11:04:12] "POST /form_upload HTTP/1.1" 200 2
Performing system checks...

System check identified no issues (0 silenced).
November 06, 2018 - 11:04:00
Django version 1.10, using settings 'gentelella.settings'
Starting development server at http://0:8000/
Quit the server with CONTROL-C.
111111
[06/Nov/2018 11:23:34] "GET /form_upload.html HTTP/1.1" 200 31308
[06/Nov/2018 11:23:39] "GET /form_upload.html HTTP/1.1" 200 31308
Internal Server Error: /form_upload
Traceback (most recent call last):
  File "/usr/local/python3.6/lib/python3.6/site-packages/django/core/handlers/exception.py", line 39, in inner
    response = get_response(request)
  File "/usr/local/python3.6/lib/python3.6/site-packages/django/core/handlers/base.py", line 187, in _get_response
    response = self.process_exception_by_middleware(e, request)
  File "/usr/local/python3.6/lib/python3.6/site-packages/django/core/handlers/base.py", line 185, in _get_response
    response = wrapped_callback(request, *callback_args, **callback_kwargs)
  File "/srv/django-gentelella/gentelella/app/views.py", line 29, in form_upload
    f = open('/tmp/',filename,'w')
TypeError: an integer is required (got type str)
[06/Nov/2018 11:23:42] "POST /form_upload HTTP/1.1" 500 13908
Performing system checks...

System check identified no issues (0 silenced).
November 06, 2018 - 11:23:21
Django version 1.10, using settings 'gentelella.settings'
Starting development server at http://0:8000/
Quit the server with CONTROL-C.
[06/Nov/2018 11:25:22] "GET /form_upload.html HTTP/1.1" 200 31308
[06/Nov/2018 11:25:24] "GET /form.html HTTP/1.1" 200 41029
[06/Nov/2018 11:25:26] "GET /form_upload.html HTTP/1.1" 200 31308
Internal Server Error: /form_upload
Traceback (most recent call last):
  File "/usr/local/python3.6/lib/python3.6/site-packages/django/core/handlers/exception.py", line 39, in inner
    response = get_response(request)
  File "/usr/local/python3.6/lib/python3.6/site-packages/django/core/handlers/base.py", line 187, in _get_response
    response = self.process_exception_by_middleware(e, request)
  File "/usr/local/python3.6/lib/python3.6/site-packages/django/core/handlers/base.py", line 185, in _get_response
    response = wrapped_callback(request, *callback_args, **callback_kwargs)
  File "/srv/django-gentelella/gentelella/app/views.py", line 32, in form_upload
    f.write(chunk)
TypeError: write() argument must be str, not bytes
[06/Nov/2018 11:25:28] "POST /form_upload HTTP/1.1" 500 13900
Performing system checks...

System check identified no issues (0 silenced).
November 06, 2018 - 11:25:17
Django version 1.10, using settings 'gentelella.settings'
Starting development server at http://0:8000/
Quit the server with CONTROL-C.
[06/Nov/2018 11:26:04] "GET /form_upload.html HTTP/1.1" 200 31308
[06/Nov/2018 11:26:07] "POST /form_upload HTTP/1.1" 200 2
[06/Nov/2018 12:33:52] "POST /form_upload HTTP/1.1" 200 2
[06/Nov/2018 12:37:23] "POST /form_upload HTTP/1.1" 200 2
Performing system checks...

System check identified no issues (0 silenced).
November 06, 2018 - 11:25:59
Django version 1.10, using settings 'gentelella.settings'
Starting development server at http://0:8000/
Quit the server with CONTROL-C.
111111
111111
111111
[06/Nov/2018 12:38:51] "GET /form_upload.html HTTP/1.1" 200 31308
[06/Nov/2018 12:38:57] "POST /form_upload HTTP/1.1" 200 2
[06/Nov/2018 12:40:07] "POST /form_upload HTTP/1.1" 200 2
Performing system checks...

System check identified no issues (0 silenced).
November 06, 2018 - 12:38:36
Django version 1.10, using settings 'gentelella.settings'
Starting development server at http://0:8000/
Quit the server with CONTROL-C.
111111
111111
Unhandled exception in thread started by <function check_errors.<locals>.wrapper at 0x7fc46a386400>
Traceback (most recent call last):
  File "/usr/local/python3.6/lib/python3.6/site-packages/django/utils/autoreload.py", line 226, in wrapper
    fn(*args, **kwargs)
  File "/usr/local/python3.6/lib/python3.6/site-packages/django/core/management/commands/runserver.py", line 121, in inner_run
    self.check(display_num_errors=True)
  File "/usr/local/python3.6/lib/python3.6/site-packages/django/core/management/base.py", line 385, in check
    include_deployment_checks=include_deployment_checks,
  File "/usr/local/python3.6/lib/python3.6/site-packages/django/core/management/base.py", line 372, in _run_checks
    return checks.run_checks(**kwargs)
  File "/usr/local/python3.6/lib/python3.6/site-packages/django/core/checks/registry.py", line 81, in run_checks
    new_errors = check(app_configs=app_configs)
  File "/usr/local/python3.6/lib/python3.6/site-packages/django/core/checks/urls.py", line 14, in check_url_config
    return check_resolver(resolver)
  File "/usr/local/python3.6/lib/python3.6/site-packages/django/core/checks/urls.py", line 24, in check_resolver
    for pattern in resolver.url_patterns:
  File "/usr/local/python3.6/lib/python3.6/site-packages/django/utils/functional.py", line 35, in __get__
    res = instance.__dict__[self.name] = self.func(instance)
  File "/usr/local/python3.6/lib/python3.6/site-packages/django/urls/resolvers.py", line 310, in url_patterns
    patterns = getattr(self.urlconf_module, "urlpatterns", self.urlconf_module)
  File "/usr/local/python3.6/lib/python3.6/site-packages/django/utils/functional.py", line 35, in __get__
    res = instance.__dict__[self.name] = self.func(instance)
  File "/usr/local/python3.6/lib/python3.6/site-packages/django/urls/resolvers.py", line 303, in urlconf_module
    return import_module(self.urlconf_name)
  File "/usr/local/python3.6/lib/python3.6/importlib/__init__.py", line 126, in import_module
    return _bootstrap._gcd_import(name[level:], package, level)
  File "<frozen importlib._bootstrap>", line 994, in _gcd_import
  File "<frozen importlib._bootstrap>", line 971, in _find_and_load
  File "<frozen importlib._bootstrap>", line 955, in _find_and_load_unlocked
  File "<frozen importlib._bootstrap>", line 665, in _load_unlocked
  File "<frozen importlib._bootstrap_external>", line 678, in exec_module
  File "<frozen importlib._bootstrap>", line 219, in _call_with_frames_removed
  File "/srv/django-gentelella/gentelella/gentelella/urls.py", line 23, in <module>
    url(r'^app/', include('app.urls')),
  File "/usr/local/python3.6/lib/python3.6/site-packages/django/conf/urls/__init__.py", line 50, in include
    urlconf_module = import_module(urlconf_module)
  File "/usr/local/python3.6/lib/python3.6/importlib/__init__.py", line 126, in import_module
    return _bootstrap._gcd_import(name[level:], package, level)
  File "<frozen importlib._bootstrap>", line 994, in _gcd_import
  File "<frozen importlib._bootstrap>", line 971, in _find_and_load
  File "<frozen importlib._bootstrap>", line 955, in _find_and_load_unlocked
  File "<frozen importlib._bootstrap>", line 665, in _load_unlocked
  File "<frozen importlib._bootstrap_external>", line 678, in exec_module
  File "<frozen importlib._bootstrap>", line 219, in _call_with_frames_removed
  File "/srv/django-gentelella/gentelella/app/urls.py", line 2, in <module>
    from app import views
  File "/srv/django-gentelella/gentelella/app/views.py", line 29
    import docx import Document
                     ^
SyntaxError: invalid syntax
Performing system checks...

Unhandled exception in thread started by <function check_errors.<locals>.wrapper at 0x7f6f5d145400>
Traceback (most recent call last):
  File "/usr/local/python3.6/lib/python3.6/site-packages/django/utils/autoreload.py", line 226, in wrapper
    fn(*args, **kwargs)
  File "/usr/local/python3.6/lib/python3.6/site-packages/django/core/management/commands/runserver.py", line 121, in inner_run
    self.check(display_num_errors=True)
  File "/usr/local/python3.6/lib/python3.6/site-packages/django/core/management/base.py", line 385, in check
    include_deployment_checks=include_deployment_checks,
  File "/usr/local/python3.6/lib/python3.6/site-packages/django/core/management/base.py", line 372, in _run_checks
    return checks.run_checks(**kwargs)
  File "/usr/local/python3.6/lib/python3.6/site-packages/django/core/checks/registry.py", line 81, in run_checks
    new_errors = check(app_configs=app_configs)
  File "/usr/local/python3.6/lib/python3.6/site-packages/django/core/checks/urls.py", line 14, in check_url_config
    return check_resolver(resolver)
  File "/usr/local/python3.6/lib/python3.6/site-packages/django/core/checks/urls.py", line 24, in check_resolver
    for pattern in resolver.url_patterns:
  File "/usr/local/python3.6/lib/python3.6/site-packages/django/utils/functional.py", line 35, in __get__
    res = instance.__dict__[self.name] = self.func(instance)
  File "/usr/local/python3.6/lib/python3.6/site-packages/django/urls/resolvers.py", line 310, in url_patterns
    patterns = getattr(self.urlconf_module, "urlpatterns", self.urlconf_module)
  File "/usr/local/python3.6/lib/python3.6/site-packages/django/utils/functional.py", line 35, in __get__
    res = instance.__dict__[self.name] = self.func(instance)
  File "/usr/local/python3.6/lib/python3.6/site-packages/django/urls/resolvers.py", line 303, in urlconf_module
    return import_module(self.urlconf_name)
  File "/usr/local/python3.6/lib/python3.6/importlib/__init__.py", line 126, in import_module
    return _bootstrap._gcd_import(name[level:], package, level)
  File "<frozen importlib._bootstrap>", line 994, in _gcd_import
  File "<frozen importlib._bootstrap>", line 971, in _find_and_load
  File "<frozen importlib._bootstrap>", line 955, in _find_and_load_unlocked
  File "<frozen importlib._bootstrap>", line 665, in _load_unlocked
  File "<frozen importlib._bootstrap_external>", line 678, in exec_module
  File "<frozen importlib._bootstrap>", line 219, in _call_with_frames_removed
  File "/srv/django-gentelella/gentelella/gentelella/urls.py", line 23, in <module>
    url(r'^app/', include('app.urls')),
  File "/usr/local/python3.6/lib/python3.6/site-packages/django/conf/urls/__init__.py", line 50, in include
    urlconf_module = import_module(urlconf_module)
  File "/usr/local/python3.6/lib/python3.6/importlib/__init__.py", line 126, in import_module
    return _bootstrap._gcd_import(name[level:], package, level)
  File "<frozen importlib._bootstrap>", line 994, in _gcd_import
  File "<frozen importlib._bootstrap>", line 971, in _find_and_load
  File "<frozen importlib._bootstrap>", line 955, in _find_and_load_unlocked
  File "<frozen importlib._bootstrap>", line 665, in _load_unlocked
  File "<frozen importlib._bootstrap_external>", line 678, in exec_module
  File "<frozen importlib._bootstrap>", line 219, in _call_with_frames_removed
  File "/srv/django-gentelella/gentelella/app/urls.py", line 2, in <module>
    from app import views
  File "/srv/django-gentelella/gentelella/app/views.py", line 29
    import docx import Document
                     ^
SyntaxError: invalid syntax
Performing system checks...

Unhandled exception in thread started by <function check_errors.<locals>.wrapper at 0x7f38a3995400>
Traceback (most recent call last):
  File "/usr/local/python3.6/lib/python3.6/site-packages/django/utils/autoreload.py", line 226, in wrapper
    fn(*args, **kwargs)
  File "/usr/local/python3.6/lib/python3.6/site-packages/django/core/management/commands/runserver.py", line 121, in inner_run
    self.check(display_num_errors=True)
  File "/usr/local/python3.6/lib/python3.6/site-packages/django/core/management/base.py", line 385, in check
    include_deployment_checks=include_deployment_checks,
  File "/usr/local/python3.6/lib/python3.6/site-packages/django/core/management/base.py", line 372, in _run_checks
    return checks.run_checks(**kwargs)
  File "/usr/local/python3.6/lib/python3.6/site-packages/django/core/checks/registry.py", line 81, in run_checks
    new_errors = check(app_configs=app_configs)
  File "/usr/local/python3.6/lib/python3.6/site-packages/django/core/checks/urls.py", line 14, in check_url_config
    return check_resolver(resolver)
  File "/usr/local/python3.6/lib/python3.6/site-packages/django/core/checks/urls.py", line 24, in check_resolver
    for pattern in resolver.url_patterns:
  File "/usr/local/python3.6/lib/python3.6/site-packages/django/utils/functional.py", line 35, in __get__
    res = instance.__dict__[self.name] = self.func(instance)
  File "/usr/local/python3.6/lib/python3.6/site-packages/django/urls/resolvers.py", line 310, in url_patterns
    patterns = getattr(self.urlconf_module, "urlpatterns", self.urlconf_module)
  File "/usr/local/python3.6/lib/python3.6/site-packages/django/utils/functional.py", line 35, in __get__
    res = instance.__dict__[self.name] = self.func(instance)
  File "/usr/local/python3.6/lib/python3.6/site-packages/django/urls/resolvers.py", line 303, in urlconf_module
    return import_module(self.urlconf_name)
  File "/usr/local/python3.6/lib/python3.6/importlib/__init__.py", line 126, in import_module
    return _bootstrap._gcd_import(name[level:], package, level)
  File "<frozen importlib._bootstrap>", line 994, in _gcd_import
  File "<frozen importlib._bootstrap>", line 971, in _find_and_load
  File "<frozen importlib._bootstrap>", line 955, in _find_and_load_unlocked
  File "<frozen importlib._bootstrap>", line 665, in _load_unlocked
  File "<frozen importlib._bootstrap_external>", line 678, in exec_module
  File "<frozen importlib._bootstrap>", line 219, in _call_with_frames_removed
  File "/srv/django-gentelella/gentelella/gentelella/urls.py", line 23, in <module>
    url(r'^app/', include('app.urls')),
  File "/usr/local/python3.6/lib/python3.6/site-packages/django/conf/urls/__init__.py", line 50, in include
    urlconf_module = import_module(urlconf_module)
  File "/usr/local/python3.6/lib/python3.6/importlib/__init__.py", line 126, in import_module
    return _bootstrap._gcd_import(name[level:], package, level)
  File "<frozen importlib._bootstrap>", line 994, in _gcd_import
  File "<frozen importlib._bootstrap>", line 971, in _find_and_load
  File "<frozen importlib._bootstrap>", line 955, in _find_and_load_unlocked
  File "<frozen importlib._bootstrap>", line 665, in _load_unlocked
  File "<frozen importlib._bootstrap_external>", line 678, in exec_module
  File "<frozen importlib._bootstrap>", line 219, in _call_with_frames_removed
  File "/srv/django-gentelella/gentelella/app/urls.py", line 2, in <module>
    from app import views
  File "/srv/django-gentelella/gentelella/app/views.py", line 29
    import docx import Document
                     ^
SyntaxError: invalid syntax
Performing system checks...

[06/Nov/2018 13:04:20] "GET / HTTP/1.1" 200 43415
[06/Nov/2018 13:04:27] "GET /form.html HTTP/1.1" 200 41029
[06/Nov/2018 13:04:29] "GET /form_upload.html HTTP/1.1" 200 31308
----------------------------------------
Exception happened during processing of request from ('172.20.4.15', 50287)
Traceback (most recent call last):
  File "/usr/local/python3.6/lib/python3.6/socketserver.py", line 651, in process_request_thread
    self.finish_request(request, client_address)
  File "/usr/local/python3.6/lib/python3.6/socketserver.py", line 361, in finish_request
    self.RequestHandlerClass(request, client_address, self)
  File "/usr/local/python3.6/lib/python3.6/socketserver.py", line 721, in __init__
    self.handle()
  File "/usr/local/python3.6/lib/python3.6/site-packages/django/core/servers/basehttp.py", line 159, in handle
    self.raw_requestline = self.rfile.readline(65537)
  File "/usr/local/python3.6/lib/python3.6/socket.py", line 586, in readinto
    return self._sock.recv_into(b)
ConnectionResetError: [Errno 104] Connection reset by peer
----------------------------------------
Internal Server Error: /form_upload
Traceback (most recent call last):
  File "/usr/local/python3.6/lib/python3.6/site-packages/django/core/handlers/exception.py", line 39, in inner
    response = get_response(request)
  File "/usr/local/python3.6/lib/python3.6/site-packages/django/core/handlers/base.py", line 187, in _get_response
    response = self.process_exception_by_middleware(e, request)
  File "/usr/local/python3.6/lib/python3.6/site-packages/django/core/handlers/base.py", line 185, in _get_response
    response = wrapped_callback(request, *callback_args, **callback_kwargs)
  File "/srv/django-gentelella/gentelella/app/views.py", line 29, in form_upload
    from docx import Document
ModuleNotFoundError: No module named 'docx'
[06/Nov/2018 13:04:49] "POST /form_upload HTTP/1.1" 500 13909
Internal Server Error: /form_upload
Traceback (most recent call last):
  File "/usr/local/python3.6/lib/python3.6/site-packages/django/core/handlers/exception.py", line 39, in inner
    response = get_response(request)
  File "/usr/local/python3.6/lib/python3.6/site-packages/django/core/handlers/base.py", line 187, in _get_response
    response = self.process_exception_by_middleware(e, request)
  File "/usr/local/python3.6/lib/python3.6/site-packages/django/core/handlers/base.py", line 185, in _get_response
    response = wrapped_callback(request, *callback_args, **callback_kwargs)
  File "/srv/django-gentelella/gentelella/app/views.py", line 29, in form_upload
    from docx import Document
  File "/usr/local/python3.6/lib/python3.6/site-packages/docx.py", line 30, in <module>
    from exceptions import PendingDeprecationWarning
ModuleNotFoundError: No module named 'exceptions'
[06/Nov/2018 13:05:27] "POST /form_upload HTTP/1.1" 500 14053
Performing system checks...

System check identified no issues (0 silenced).
November 06, 2018 - 13:04:11
Django version 1.10, using settings 'gentelella.settings'
Starting development server at http://0:8000/
Quit the server with CONTROL-C.
Performing system checks...

System check identified no issues (0 silenced).
November 06, 2018 - 13:06:24
Django version 1.10, using settings 'gentelella.settings'
Starting development server at http://0:8000/
Quit the server with CONTROL-C.
[06/Nov/2018 13:10:09] "GET /form_upload.html HTTP/1.1" 200 31308
Internal Server Error: /form_upload
Traceback (most recent call last):
  File "/usr/local/python3.6/lib/python3.6/site-packages/django/core/handlers/exception.py", line 39, in inner
    response = get_response(request)
  File "/usr/local/python3.6/lib/python3.6/site-packages/django/core/handlers/base.py", line 187, in _get_response
    response = self.process_exception_by_middleware(e, request)
  File "/usr/local/python3.6/lib/python3.6/site-packages/django/core/handlers/base.py", line 185, in _get_response
    response = wrapped_callback(request, *callback_args, **callback_kwargs)
  File "/srv/django-gentelella/gentelella/app/views.py", line 29, in form_upload
    from docx import Document
  File "/usr/local/python3.6/lib/python3.6/site-packages/docx.py", line 30, in <module>
    from exceptions import PendingDeprecationWarning
ModuleNotFoundError: No module named 'exceptions'
[06/Nov/2018 13:10:13] "POST /form_upload HTTP/1.1" 500 14053
Performing system checks...

System check identified no issues (0 silenced).
November 06, 2018 - 13:09:56
Django version 1.10, using settings 'gentelella.settings'
Starting development server at http://0:8000/
Quit the server with CONTROL-C.
[06/Nov/2018 13:13:07] "POST /form_upload HTTP/1.1" 200 2
Performing system checks...

System check identified no issues (0 silenced).
November 06, 2018 - 13:12:58
Django version 1.10, using settings 'gentelella.settings'
Starting development server at http://0:8000/
Quit the server with CONTROL-C.
111111
[06/Nov/2018 13:21:26] "GET /form.html HTTP/1.1" 200 41029
[06/Nov/2018 13:21:28] "GET /form_upload.html HTTP/1.1" 200 31308
Internal Server Error: /form_upload
Traceback (most recent call last):
  File "/usr/local/python3.6/lib/python3.6/site-packages/django/core/handlers/exception.py", line 39, in inner
    response = get_response(request)
  File "/usr/local/python3.6/lib/python3.6/site-packages/django/core/handlers/base.py", line 187, in _get_response
    response = self.process_exception_by_middleware(e, request)
  File "/usr/local/python3.6/lib/python3.6/site-packages/django/core/handlers/base.py", line 185, in _get_response
    response = wrapped_callback(request, *callback_args, **callback_kwargs)
  File "/srv/django-gentelella/gentelella/app/views.py", line 33, in form_upload
    f.write(str("---"))
TypeError: a bytes-like object is required, not 'str'
[06/Nov/2018 13:21:31] "POST /form_upload HTTP/1.1" 500 13927
Performing system checks...

System check identified no issues (0 silenced).
November 06, 2018 - 13:21:19
Django version 1.10, using settings 'gentelella.settings'
Starting development server at http://0:8000/
Quit the server with CONTROL-C.
Internal Server Error: /form_upload
Traceback (most recent call last):
  File "/usr/local/python3.6/lib/python3.6/site-packages/django/core/handlers/exception.py", line 39, in inner
    response = get_response(request)
  File "/usr/local/python3.6/lib/python3.6/site-packages/django/core/handlers/base.py", line 187, in _get_response
    response = self.process_exception_by_middleware(e, request)
  File "/usr/local/python3.6/lib/python3.6/site-packages/django/core/handlers/base.py", line 185, in _get_response
    response = wrapped_callback(request, *callback_args, **callback_kwargs)
  File "/srv/django-gentelella/gentelella/app/views.py", line 33, in form_upload
    f.write("---")
TypeError: a bytes-like object is required, not 'str'
[06/Nov/2018 13:21:58] "POST /form_upload HTTP/1.1" 500 13922
Performing system checks...

System check identified no issues (0 silenced).
November 06, 2018 - 13:21:53
Django version 1.10, using settings 'gentelella.settings'
Starting development server at http://0:8000/
Quit the server with CONTROL-C.
[06/Nov/2018 13:23:10] "GET /form_upload.html HTTP/1.1" 200 31308
Internal Server Error: /form_upload
Traceback (most recent call last):
  File "/usr/local/python3.6/lib/python3.6/site-packages/django/core/handlers/exception.py", line 39, in inner
    response = get_response(request)
  File "/usr/local/python3.6/lib/python3.6/site-packages/django/core/handlers/base.py", line 187, in _get_response
    response = self.process_exception_by_middleware(e, request)
  File "/usr/local/python3.6/lib/python3.6/site-packages/django/core/handlers/base.py", line 185, in _get_response
    response = wrapped_callback(request, *callback_args, **callback_kwargs)
  File "/srv/django-gentelella/gentelella/app/views.py", line 33, in form_upload
    f.write(con)
TypeError: a bytes-like object is required, not 'str'
[06/Nov/2018 13:23:14] "POST /form_upload HTTP/1.1" 500 13920
Performing system checks...

System check identified no issues (0 silenced).
November 06, 2018 - 13:23:04
Django version 1.10, using settings 'gentelella.settings'
Starting development server at http://0:8000/
Quit the server with CONTROL-C.
[06/Nov/2018 13:23:41] "GET /form_upload.html HTTP/1.1" 200 31308
Internal Server Error: /form_upload
Traceback (most recent call last):
  File "/usr/local/python3.6/lib/python3.6/site-packages/django/core/handlers/exception.py", line 39, in inner
    response = get_response(request)
  File "/usr/local/python3.6/lib/python3.6/site-packages/django/core/handlers/base.py", line 187, in _get_response
    response = self.process_exception_by_middleware(e, request)
  File "/usr/local/python3.6/lib/python3.6/site-packages/django/core/handlers/base.py", line 185, in _get_response
    response = wrapped_callback(request, *callback_args, **callback_kwargs)
  File "/srv/django-gentelella/gentelella/app/views.py", line 33, in form_upload
    f.write(con)
TypeError: a bytes-like object is required, not 'str'
[06/Nov/2018 13:23:45] "POST /form_upload HTTP/1.1" 500 13920
Performing system checks...

System check identified no issues (0 silenced).
November 06, 2018 - 13:23:38
Django version 1.10, using settings 'gentelella.settings'
Starting development server at http://0:8000/
Quit the server with CONTROL-C.
Internal Server Error: /form_upload
Traceback (most recent call last):
  File "/usr/local/python3.6/lib/python3.6/site-packages/django/core/handlers/exception.py", line 39, in inner
    response = get_response(request)
  File "/usr/local/python3.6/lib/python3.6/site-packages/django/core/handlers/base.py", line 187, in _get_response
    response = self.process_exception_by_middleware(e, request)
  File "/usr/local/python3.6/lib/python3.6/site-packages/django/core/handlers/base.py", line 185, in _get_response
    response = wrapped_callback(request, *callback_args, **callback_kwargs)
  File "/srv/django-gentelella/gentelella/app/views.py", line 33, in form_upload
    f.write(con)
TypeError: a bytes-like object is required, not 'str'
[06/Nov/2018 13:24:14] "POST /form_upload HTTP/1.1" 500 13920
Performing system checks...

System check identified no issues (0 silenced).
November 06, 2018 - 13:24:10
Django version 1.10, using settings 'gentelella.settings'
Starting development server at http://0:8000/
Quit the server with CONTROL-C.
[06/Nov/2018 13:26:49] "GET /form_upload.html HTTP/1.1" 200 31308
[06/Nov/2018 13:26:52] "POST /form_upload HTTP/1.1" 200 2
